Workbook

Sheet Sprint 1
A1: Project name: | C1: Xây dựng hệ thống thương mại điện tử mỹ phẩm Hamoni Cosmetic tích hợp Chatbox AI | F1: Kết thúc đúng hạn
A2: Module name: | C2: Sprint 1 | F2: Muộn
A3: Start date: | C3: 22/03/2026 | F3: Trước thời hạn
A4: End date: | C4: 46057
B6: SPRINT 1 REPORT
B7: No | C7: Thành viên | D7: Thực tế | E7: Ước tính
B8: 1 | C8: Nguyễn Công Thành | D8: =SUMIF($E$16:$F$113,"Thành",$G$16:$G$113) +SUMIF($E$16:$F$113,"All team",$G$16:$G$113)/5 +SUMIF($E$16:$F$113,"Thành, Phương, Việt, Tấn",$G$16:$G$113)/4 -> 34.25 | E8: =SUMIF($E$16:$F$113,"Thành",$H$16:$H$113) +SUMIF($E$16:$F$113,"All team",$H$16:$H$113)/5 +SUMIF($E$16:$F$113,"Thành, Phương, Việt, Tấn",$H$16:$H$113)/4 -> 39.25
B9: 2 | C9: Nhan Thị Ngọc Nữ | D9: =SUMIF($E$16:$F$113,"Nữ",$G$16:$G$113) +SUMIF($E$16:$F$113,"All team",$G$16:$G$113)/5 -> 54 | E9: =SUMIF($E$16:$F$113,"Nữ",$H$16:$H$113) +SUMIF($E$16:$F$113,"All team",$H$16:$H$113)/5 -> 52
B10: 3 | C10: Đinh Thị Phương | D10: =SUMIF($E$16:$F$113,"Phương",$G$16:$G$113) +SUMIF($E$16:$F$113,"All team",$G$16:$G$113)/5 +SUMIF($E$16:$F$113,"Thành, Phương, Việt, Tấn",$G$16:$G$113)/4 -> 29.25 | E10: =SUMIF($E$16:$F$113,"Phương",$H$16:$H$113) +SUMIF($E$16:$F$113,"All team",$H$16:$H$113)/5 +SUMIF($E$16:$F$113,"Thành, Phương, Việt, Tấn",$H$16:$H$113)/4 -> 25.25
B11: 4 | C11: Nguyễn Quốc Tấn | D11: =SUMIF($E$16:$F$113,"Tấn",$G$16:$G$113) +SUMIF($E$16:$F$113,"All team",$G$16:$G$113)/5 +SUMIF($E$16:$F$113,"Thành, Phương, Việt, Tấn",$G$16:$G$113)/4 -> 19.25 | E11: =SUMIF($E$16:$F$113,"Tấn",$H$16:$H$113) +SUMIF($E$16:$F$113,"All team",$H$16:$H$113)/5 +SUMIF($E$16:$F$113,"Thành, Phương, Việt, Tấn",$H$16:$H$113)/4 -> 19.25
B12: 5 | C12: Phan Hồ Phi Việt | D12: =SUMIF($E$16:$F$113,"Việt",$G$16:$G$113) +SUMIF($E$16:$F$113,"All team",$G$16:$G$113)/5 +SUMIF($E$16:$F$113,"Thành, Phương, Việt, Tấn",$G$16:$G$113)/4 -> 39.25 | E12: =SUMIF($E$16:$F$113,"Việt",$H$16:$H$113) +SUMIF($E$16:$F$113,"All team",$H$16:$H$113)/5 +SUMIF($E$16:$F$113,"Thành, Phương, Việt, Tấn",$H$16:$H$113)/4 -> 37.25
B13: Tổng | D13: =SUM(D8:D12) -> 176 | E13: =SUM(E8:E12) -> 173
A15: Sprint | B15: Compoment | C15: Task name | E15: Responsible Member | G15: Thực tế | H15: Ước tính | I15: 22/03 | J15: 23/03 | K15: 24/03 | L15: 25/03 | M15: 26/03 | N15: 27/03 | O15: 28/03 | P15: 29/03 | Q15: 30/03 | R15: 31/03 | S15: 46113 | T15: 46114 | U15: 46115
A16: Sprint 1 | B16: Họp kế hoạch Sprint | E16: All team | G16: 10 | H16: 10 | I16: 10 | J16: 0 | K16: 0 | L16: 0 | M16: 0 | N16: 0 | O16: 0 | P16: 0 | Q16: 0 | R16: 0 | S16: 0 | T16: 0 | U16: 0
B17: Tạo Sprint Backlog 1 | E17: Tấn, Việt | G17: 4 | H17: 4 | I17: 4 | J17: 0 | K17: 0 | L17: 0 | M17: 0 | N17: 0 | O17: 0 | P17: 0 | Q17: 0 | R17: 0 | S17: 0 | T17: 0 | U17: 0
B18: Tạo tài liệu kiểm thử cho Sprint | E18: Nữ | G18: 4 | H18: 4 | I18: 4 | J18: 0 | K18: 0 | L18: 0 | M18: 0 | N18: 0 | O18: 0 | P18: 0 | Q18: 0 | R18: 0 | S18: 0 | T18: 0 | U18: 0
B19: User interface design | C19: Giao diện đăng kí | E19: Nữ | G19: 1 | H19: 1 | I19: 1 | J19: 0 | K19: 0 | L19: 0 | M19: 0 | N19: 0 | O19: 0 | P19: 0 | Q19: 0 | R19: 0 | S19: 0 | T19: 0 | U19: 0
C20: Giao diện đăng nhập | E20: Nữ | G20: 1 | H20: 1 | I20: 1 | J20: 0 | K20: 0 | L20: 0 | M20: 0 | N20: 0 | O20: 0 | P20: 0 | Q20: 0 | R20: 0 | S20: 0 | T20: 0 | U20: 0
C21: Giao diện đăng xuất | E21: Nữ | G21: 1 | H21: 1 | I21: 1 | J21: 0 | K21: 0 | L21: 0 | M21: 0 | N21: 0 | O21: 0 | P21: 0 | Q21: 0 | R21: 0 | S21: 0 | T21: 0 | U21: 0
C22: Giao diện cập nhật thông tin | E22: Nữ | G22: 1 | H22: 1 | I22: 1 | J22: 0 | K22: 0 | L22: 0 | M22: 0 | N22: 0 | O22: 0 | P22: 0 | Q22: 0 | R22: 0 | S22: 0 | T22: 0 | U22: 0
C23: Giao diện phân quyền người dùng | E23: Nữ | G23: 1 | H23: 1 | I23: 1 | J23: 1 | K23: 0 | L23: 0 | M23: 0 | N23: 0 | O23: 0 | P23: 0 | Q23: 0 | R23: 0 | S23: 0 | T23: 0 | U23: 0
C24: Giao diện quản lý khách hàng | E24: Nữ | G24: 1 | H24: 1 | I24: 1 | J24: 1 | K24: 0 | L24: 0 | M24: 0 | N24: 0 | O24: 0 | P24: 0 | Q24: 0 | R24: 0 | S24: 0 | T24: 0 | U24: 0
C25: Giao diện quản lý danh mục sản phẩm | E25: Nữ | G25: 1 | H25: 1 | I25: 1 | J25: 1 | K25: 0 | L25: 0 | M25: 0 | N25: 0 | O25: 0 | P25: 0 | Q25: 0 | R25: 0 | S25: 0 | T25: 0 | U25: 0
C26: Giao diện quản lý banner | E26: Nữ | G26: 1 | H26: 1 | I26: 1 | J26: 1 | K26: 0 | L26: 0 | M26: 0 | N26: 0 | O26: 0 | P26: 0 | Q26: 0 | R26: 0 | S26: 0 | T26: 0 | U26: 0
C27: Giao diện quản lý sản phẩm | E27: Nữ | G27: 1 | H27: 1 | I27: 1 | J27: 1 | K27: 0 | L27: 0 | M27: 0 | N27: 0 | O27: 0 | P27: 0 | Q27: 0 | R27: 0 | S27: 0 | T27: 0 | U27: 0
C28: Giao diện quản lý nhân viên | E28: Nữ | G28: 1 | H28: 1 | I28: 1 | J28: 1 | K28: 0 | L28: 0 | M28: 0 | N28: 0 | O28: 0 | P28: 0 | Q28: 0 | R28: 0 | S28: 0 | T28: 0 | U28: 0
C29: Giao diện trang chủ | E29: Nữ | G29: 1 | H29: 1 | I29: 1 | J29: 1 | K29: 0 | L29: 0 | M29: 0 | N29: 0 | O29: 0 | P29: 0 | Q29: 0 | R29: 0 | S29: 0 | T29: 0 | U29: 0
C30: Review all user interfaces of sprint 1 | E30: All team | G30: 5 | H30: 5 | I30: 5 | J30: 5 | K30: 5 | L30: 0 | M30: 0 | N30: 0 | O30: 0 | P30: 0 | Q30: 0 | R30: 0 | S30: 0 | T30: 0 | U30: 0
B31: Design test case | C31: Thiết kế trường kiểm thử cho đăng kí | E31: Phương | G31: 1 | H31: 1 | I31: 1 | J31: 1 | K31: 1 | L31: 0 | M31: 0 | N31: 0 | O31: 0 | P31: 0 | Q31: 0 | R31: 0 | S31: 0 | T31: 0 | U31: 0
C32: Thiết kế trường kiểm thử cho đăng nhập | E32: Phương | G32: 1 | H32: 1 | I32: 1 | J32: 1 | K32: 1 | L32: 0 | M32: 0 | N32: 0 | O32: 0 | P32: 0 | Q32: 0 | R32: 0 | S32: 0 | T32: 0 | U32: 0
C33: Thiết kế trường kiểm thử cho đăng xuất | E33: Phương | G33: 1 | H33: 1 | I33: 1 | J33: 1 | K33: 1 | L33: 0 | M33: 0 | N33: 0 | O33: 0 | P33: 0 | Q33: 0 | R33: 0 | S33: 0 | T33: 0 | U33: 0
C34: Thiết kế trường kiểm thử cho cập nhật thông tin | E34: Tấn | G34: 1 | H34: 1 | I34: 1 | J34: 1 | K34: 1 | L34: 0 | M34: 0 | N34: 0 | O34: 0 | P34: 0 | Q34: 0 | R34: 0 | S34: 0 | T34: 0 | U34: 0
C35: Thiết kế trường kiểm thử cho phân quyền người dùng | E35: Thành | G35: 1 | H35: 1 | I35: 1 | J35: 1 | K35: 1 | L35: 0 | M35: 0 | N35: 0 | O35: 0 | P35: 0 | Q35: 0 | R35: 0 | S35: 0 | T35: 0 | U35: 0
C36: Thiết kế trường kiểm thử cho quản lý khách hàng | E36: Tấn | G36: 1 | H36: 1 | I36: 1 | J36: 1 | K36: 1 | L36: 0 | M36: 0 | N36: 0 | O36: 0 | P36: 0 | Q36: 0 | R36: 0 | S36: 0 | T36: 0 | U36: 0
C37: Thiết kế trường kiểm thử cho quản lý danh mục sản phẩm | E37: Việt | G37: 1 | H37: 1 | I37: 1 | J37: 1 | K37: 1 | L37: 0 | M37: 0 | N37: 0 | O37: 0 | P37: 0 | Q37: 0 | R37: 0 | S37: 0 | T37: 0 | U37: 0
C38: Thiết kế trường kiểm thử cho quản lý banner | E38: Việt | G38: 1 | H38: 1 | I38: 1 | J38: 1 | K38: 1 | L38: 1 | M38: 0 | N38: 0 | O38: 0 | P38: 0 | Q38: 0 | R38: 0 | S38: 0 | T38: 0 | U38: 0
C39: Thiết kế trường kiểm thử cho quản lý sản phẩm | E39: Thành | G39: 1 | H39: 1 | I39: 1 | J39: 1 | K39: 1 | L39: 1 | M39: 0 | N39: 0 | O39: 0 | P39: 0 | Q39: 0 | R39: 0 | S39: 0 | T39: 0 | U39: 0
C40: Thiết kế trường kiểm thử cho quản lý nhân viên | E40: Việt | G40: 1 | H40: 1 | I40: 1 | J40: 1 | K40: 1 | L40: 1 | M40: 0 | N40: 0 | O40: 0 | P40: 0 | Q40: 0 | R40: 0 | S40: 0 | T40: 0 | U40: 0
C41: Thiết kế trường kiểm thử cho trang chủ | E41: Thành | G41: 1 | H41: 1 | I41: 1 | J41: 1 | K41: 1 | L41: 1 | M41: 0 | N41: 0 | O41: 0 | P41: 0 | Q41: 0 | R41: 0 | S41: 0 | T41: 0 | U41: 0
C42: Review all test case of sprint 1 | E42: All team | G42: 5 | H42: 5 | I42: 5 | J42: 5 | K42: 5 | L42: 5 | M42: 5 | N42: 0 | O42: 0 | P42: 0 | Q42: 0 | R42: 0 | S42: 0 | T42: 0 | U42: 0
...

Sheet Sprint 2
A1: Project name: | C1: Xây dựng hệ thống thương mại điện tử mỹ phẩm Hamoni Cosmetic tích hợp Chatbox AI | F1: Kết thúc đúng hạn
A2: Module name: | C2: Sprint 2 | F2: Muộn
A3: Start date: | C3: 46057 | F3: Trước thời hạn
A4: End date: | C4: 22/04/2026
B6: SPRINT 2 REPORT
B7: No | C7: Thành viên | D7: Thực tế | E7: Ước tính
B8: 1 | C8: Nguyễn Công Thành | D8: =SUMIF($E$16:$F$105,"Thành",$G$16:$G$105) +SUMIF($E$16:$F$105,"All team",$G$16:$G$105)/5 +SUMIF($E$16:$F$105,"Thành, Phương, Việt, Tấn",$G$16:$G$105)/4 -> 58.25 | E8: =SUMIF($E$16:$F$105,"Thành",$H$16:$H$105) +SUMIF($E$16:$F$105,"All team",$H$16:$H$105)/5 +SUMIF($E$16:$F$105,"Thành, Phương, Việt, Tấn",$H$16:$H$105)/4 -> 59.25
B9: 2 | C9: Nhan Thị Ngọc Nữ | D9: =SUMIF($E$16:$F$105,"Nữ",$G$16:$G$105) +SUMIF($E$16:$F$105,"All team",$G$16:$G$105)/5 -> 58 | E9: =SUMIF($E$16:$F$105,"Nữ",$H$16:$H$105) +SUMIF($E$16:$F$105,"All team",$H$16:$H$105)/5 -> 56
B10: 3 | C10: Đinh Thị Phương | D10: =SUMIF($E$16:$F$105,"Phương",$G$16:$G$105) +SUMIF($E$16:$F$105,"All team",$G$16:$G$105)/5 +SUMIF($E$16:$F$105,"Thành, Phương, Việt, Tấn",$G$16:$G$105)/4 -> 50.25 | E10: =SUMIF($E$16:$F$105,"Phương",$H$16:$H$105) +SUMIF($E$16:$F$105,"All team",$H$16:$H$105)/5 +SUMIF($E$16:$F$105,"Thành, Phương, Việt, Tấn",$H$16:$H$105)/4 -> 49.25
B11: 4 | C11: Nguyễn Quốc Tấn | D11: =SUMIF($E$16:$F$105,"Tấn",$G$16:$G$105) +SUMIF($E$16:$F$105,"All team",$G$16:$G$105)/5 +SUMIF($E$16:$F$105,"Thành, Phương, Việt, Tấn",$G$16:$G$105)/4 -> 54.25 | E11: =SUMIF($E$16:$F$105,"Tấn",$H$16:$H$105) +SUMIF($E$16:$F$105,"All team",$H$16:$H$105)/5 +SUMIF($E$16:$F$105,"Thành, Phương, Việt, Tấn",$H$16:$H$105)/4 -> 54.25
B12: 5 | C12: Phan Hồ Phi Việt | D12: =SUMIF($E$16:$F$105,"Việt",$G$16:$G$105) +SUMIF($E$16:$F$105,"All team",$G$16:$G$105)/5 +SUMIF($E$16:$F$105,"Thành, Phương, Việt, Tấn",$G$16:$G$105)/4 -> 22.25 | E12: =SUMIF($E$16:$F$105,"Việt",$H$16:$H$105) +SUMIF($E$16:$F$105,"All team",$H$16:$H$105)/5 +SUMIF($E$16:$F$105,"Thành, Phương, Việt, Tấn",$H$16:$H$105)/4 -> 22.25
B13: Tổng | D13: =SUM(D8:D12) -> 243 | E13: =SUM(E8:E12) -> 241
A15: Sprint | B15: Compoment | C15: Task name | E15: Responsible Member | G15: Thực tế | H15: Ước tính | I15: 46114 | J15: 46115 | K15: 46116 | L15: 46117 | M15: 46118 | N15: 46119 | O15: 46120 | P15: 46121 | Q15: 46122 | R15: 46123 | S15: 46124 | T15: 46125 | U15: 46126 | V15: 46127 | W15: 46128 | X15: 46129 | Y15: 46130 | Z15: 46131 | AA15: 46132 | AB15: 46133 | AC15: 46134 | AD15: 46135
A16: Sprint 2 | B16: Họp kế hoạch Sprint | E16: All team | G16: 5 | H16: 5 | I16: 5 | J16: 0 | K16: 0 | L16: 0 | M16: 0 | N16: 0 | O16: 0 | P16: 0 | Q16: 0 | R16: 0 | S16: 0 | T16: 0 | U16: 0 | V16: 0 | W16: 0 | X16: 0 | Y16: 0 | Z16: 0 | AA16: 0 | AB16: 0 | AC16: 0 | AD16: 0
B17: Tạo Sprint Backlog 2 | E17: Tấn, Việt | G17: 5 | H17: 5 | I17: 5 | J17: 0 | K17: 0 | L17: 0 | M17: 0 | N17: 0 | O17: 0 | P17: 0 | Q17: 0 | R17: 0 | S17: 0 | T17: 0 | U17: 0 | V17: 0 | W17: 0 | X17: 0 | Y17: 0 | Z17: 0 | AA17: 0 | AB17: 0 | AC17: 0 | AD17: 0
B18: Tạo tài liệu kiểm thử cho Sprint | E18: Nữ | G18: 1 | H18: 1 | I18: 1 | J18: 0 | K18: 0 | L18: 0 | M18: 0 | N18: 0 | O18: 0 | P18: 0 | Q18: 0 | R18: 0 | S18: 0 | T18: 0 | U18: 0 | V18: 0 | W18: 0 | X18: 0 | Y18: 0 | Z18: 0 | AA18: 0 | AB18: 0 | AC18: 0 | AD18: 0
B19: User interface design | C19: Giao diện xeam chi tiết đơn hàng | E19: Nữ | G19: 1 | H19: 1 | I19: 1 | J19: 0 | K19: 0 | L19: 0 | M19: 0 | N19: 0 | O19: 0 | P19: 0 | Q19: 0 | R19: 0 | S19: 0 | T19: 0 | U19: 0 | V19: 0 | W19: 0 | X19: 0 | Y19: 0 | Z19: 0 | AA19: 0 | AB19: 0 | AC19: 0 | AD19: 0
C20: Giao diện xem lịch sử đơn hàng | E20: Nữ | G20: 1 | H20: 1 | I20: 1 | J20: 0 | K20: 0 | L20: 0 | M20: 0 | N20: 0 | O20: 0 | P20: 0 | Q20: 0 | R20: 0 | S20: 0 | T20: 0 | U20: 0 | V20: 0 | W20: 0 | X20: 0 | Y20: 0 | Z20: 0 | AA20: 0 | AB20: 0 | AC20: 0 | AD20: 0
C21: Giao diện quản lý kho | E21: Nữ | G21: 1 | H21: 1 | I21: 1 | J21: 0 | K21: 0 | L21: 0 | M21: 0 | N21: 0 | O21: 0 | P21: 0 | Q21: 0 | R21: 0 | S21: 0 | T21: 0 | U21: 0 | V21: 0 | W21: 0 | X21: 0 | Y21: 0 | Z21: 0 | AA21: 0 | AB21: 0 | AC21: 0 | AD21: 0
C22: Giao diện thống kê báo cáo | E22: Nữ | G22: 2 | H22: 1 | I22: 1 | J22: 1 | K22: 0 | L22: 0 | M22: 0 | N22: 0 | O22: 0 | P22: 0 | Q22: 0 | R22: 0 | S22: 0 | T22: 0 | U22: 0 | V22: 0 | W22: 0 | X22: 0 | Y22: 0 | Z22: 0 | AA22: 0 | AB22: 0 | AC22: 0 | AD22: 0
K23: 1
C24: Giao diện đánh giá sản phẩm | E24: Nữ | G24: 1 | H24: 1 | I24: 1 | J24: 1 | K24: 0 | L24: 0 | M24: 0 | N24: 0 | O24: 0 | P24: 0 | Q24: 0 | R24: 0 | S24: 0 | T24: 0 | U24: 0 | V24: 0 | W24: 0 | X24: 0 | Y24: 0 | Z24: 0 | AA24: 0 | AB24: 0 | AC24: 0 | AD24: 0
C25: Giao diện quản lý khuyến mãi | E25: Nữ | G25: 1 | H25: 1 | I25: 1 | J25: 1 | K25: 0 | L25: 0 | M25: 0 | N25: 0 | O25: 0 | P25: 0 | Q25: 0 | R25: 0 | S25: 0 | T25: 0 | U25: 0 | V25: 0 | W25: 0 | X25: 0 | Y25: 0 | Z25: 0 | AA25: 0 | AB25: 0 | AC25: 0 | AD25: 0
C26: Giao diện quản lý voucher | E26: Nữ | G26: 1 | H26: 1 | I26: 1 | J26: 1 | K26: 0 | L26: 0 | M26: 0 | N26: 0 | O26: 0 | P26: 0 | Q26: 0 | R26: 0 | S26: 0 | T26: 0 | U26: 0 | V26: 0 | W26: 0 | X26: 0 | Y26: 0 | Z26: 0 | AA26: 0 | AB26: 0 | AC26: 0 | AD26: 0
C27: Giao diện quản lý đơn hàng | E27: Nữ | G27: 1 | H27: 1 | I27: 1 | J27: 1 | K27: 1 | L27: 0 | M27: 0 | N27: 0 | O27: 0 | P27: 0 | Q27: 0 | R27: 0 | S27: 0 | T27: 0 | U27: 0 | V27: 0 | W27: 0 | X27: 0 | Y27: 0 | Z27: 0 | AA27: 0 | AB27: 0 | AC27: 0 | AD27: 0
C28: Giao diện quản lý đánh giá | E28: Nữ | G28: 1 | H28: 1 | I28: 1 | J28: 1 | K28: 1 | L28: 0 | M28: 0 | N28: 0 | O28: 0 | P28: 0 | Q28: 0 | R28: 0 | S28: 0 | T28: 0 | U28: 0 | V28: 0 | W28: 0 | X28: 0 | Y28: 0 | Z28: 0 | AA28: 0 | AB28: 0 | AC28: 0 | AD28: 0
C29: Giao diện quản lý chatbot | E29: Nữ | G29: 1 | H29: 1 | I29: 1 | J29: 1 | K29: 1 | L29: 0 | M29: 0 | N29: 0 | O29: 0 | P29: 0 | Q29: 0 | R29: 0 | S29: 0 | T29: 0 | U29: 0 | V29: 0 | W29: 0 | X29: 0 | Y29: 0 | Z29: 0 | AA29: 0 | AB29: 0 | AC29: 0 | AD29: 0
C30: Review all user interfaces of sprint 2 | E30: All team | G30: 5 | H30: 5 | I30: 5 | J30: 5 | K30: 5 | L30: 0 | M30: 0 | N30: 0 | O30: 0 | P30: 0 | Q30: 0 | R30: 0 | S30: 0 | T30: 0 | U30: 0 | V30: 0 | W30: 0 | X30: 0 | Y30: 0 | Z30: 0 | AA30: 0 | AB30: 0 | AC30: 0 | AD30: 0
B31: Design test case | C31: Thiết kế trường kiểm thử xem chi tiết đơn hàng | E31: Việt | G31: 1 | H31: 1 | I31: 1 | J31: 1 | K31: 1 | L31: 1 | M31: 0 | N31: 0 | O31: 0 | P31: 0 | Q31: 0 | R31: 0 | S31: 0 | T31: 0 | U31: 0 | V31: 0 | W31: 0 | X31: 0 | Y31: 0 | Z31: 0 | AA31: 0 | AB31: 0 | AC31: 0 | AD31: 0
C32: Thiết kế trường kiểm thử xem lịch sử đơn hàng | E32: Tấn | G32: 1 | H32: 1 | I32: 1 | J32: 1 | K32: 1 | L32: 1 | M32: 0 | N32: 0 | O32: 0 | P32: 0 | Q32: 0 | R32: 0 | S32: 0 | T32: 0 | U32: 0 | V32: 0 | W32: 0 | X32: 0 | Y32: 0 | Z32: 0 | AA32: 0 | AB32: 0 | AC32: 0 | AD32: 0
C33: Thiết kế trường kiểm thử quản lý kho | E33: Tấn | G33: 1 | H33: 1 | I33: 1 | J33: 1 | K33: 1 | L33: 1 | M33: 0 | N33: 0 | O33: 0 | P33: 0 | Q33: 0 | R33: 0 | S33: 0 | T33: 0 | U33: 0 | V33: 0 | W33: 0 | X33: 0 | Y33: 0 | Z33: 0 | AA33: 0 | AB33: 0 | AC33: 0 | AD33: 0
C34: Thiết kế trường kiểm thử thống kê báo cáo | E34: Phương | G34: 1 | H34: 1 | I34: 1 | J34: 1 | K34: 1 | L34: 1 | M34: 0 | N34: 0 | O34: 0 | P34: 0 | Q34: 0 | R34: 0 | S34: 0 | T34: 0 | U34: 0 | V34: 0 | W34: 0 | X34: 0 | Y34: 0 | Z34: 0 | AA34: 0 | AB34: 0 | AC34: 0 | AD34: 0
C35: Thiết kế trường kiểm thử đánh giá sản phẩm | E35: Phương | G35: 1 | H35: 1 | I35: 1 | J35: 1 | K35: 1 | L35: 1 | M35: 0 | N35: 0 | O35: 0 | P35: 0 | Q35: 0 | R35: 0 | S35: 0 | T35: 0 | U35: 0 | V35: 0 | W35: 0 | X35: 0 | Y35: 0 | Z35: 0 | AA35: 0 | AB35: 0 | AC35: 0 | AD35: 0
C36: Thiết kế trường kiểm thử quản lý khuyến mãi | E36: Thành | G36: 1 | H36: 1 | I36: 1 | J36: 1 | K36: 1 | L36: 1 | M36: 0 | N36: 0 | O36: 0 | P36: 0 | Q36: 0 | R36: 0 | S36: 0 | T36: 0 | U36: 0 | V36: 0 | W36: 0 | X36: 0 | Y36: 0 | Z36: 0 | AA36: 0 | AB36: 0 | AC36: 0 | AD36: 0
C37: Thiết kế trường kiểm thử quản lý voucher | E37: Thành | G37: 1 | H37: 1 | I37: 1 | J37: 1 | K37: 1 | L37: 1 | M37: 1 | N37: 0 | O37: 0 | P37: 0 | Q37: 0 | R37: 0 | S37: 0 | T37: 0 | U37: 0 | V37: 0 | W37: 0 | X37: 0 | Y37: 0 | Z37: 0 | AA37: 0 | AB37: 0 | AC37: 0 | AD37: 0
C38: Thiết kế trường kiểm thử quản lý đơn hàng | E38: Tấn | G38: 1 | H38: 1 | I38: 1 | J38: 1 | K38: 1 | L38: 1 | M38: 1 | N38: 0 | O38: 0 | P38: 0 | Q38: 0 | R38: 0 | S38: 0 | T38: 0 | U38: 0 | V38: 0 | W38: 0 | X38: 0 | Y38: 0 | Z38: 0 | AA38: 0 | AB38: 0 | AC38: 0 | AD38: 0
C39: Thiết kế trường kiểm thử quản lý đánh giá | E39: Phương | G39: 2 | H39: 1 | I39: 0 | J39: 0 | K39: 0 | L39: 0 | M39: 0 | N39: 0 | O39: 0 | P39: 0 | Q39: 0 | R39: 0 | S39: 0 | T39: 0 | U39: 0 | V39: 0 | W39: 0 | X39: 0 | Y39: 0 | Z39: 0 | AA39: 0 | AB39: 0 | AC39: 0 | AD39: 0
N40: 1
C41: Thiết kế trường kiểm thử quản lý chatbot | E41: Thành | G41: 1 | H41: 1 | I41: 1 | J41: 1 | K41: 1 | L41: 1 | M41: 1 | N41: 0 | O41: 0 | P41: 0 | Q41: 0 | R41: 0 | S41: 0 | T41: 0 | U41: 0 | V41: 0 | W41: 0 | X41: 0 | Y41: 0 | Z41: 0 | AA41: 0 | AB41: 0 | AC41: 0 | AD41: 0
C42: Review all test case of sprint 1 | E42: All team | G42: 5 | H42: 5 | I42: 5 | J42: 5 | K42: 5 | L42: 5 | M42: 5 | N42: 0 | O42: 0 | P42: 0 | Q42: 0 | R42: 0 | S42: 0 | T42: 0 | U42: 0 | V42: 0 | W42: 0 | X42: 0 | Y42: 0 | Z42: 0 | AA42: 0 | AB42: 0 | AC42: 0 | AD42: 0
...

Sheet Sprint 3
A1: Project name: | C1: Xây dựng hệ thống thương mại điện tử mỹ phẩm Hamoni Cosmetic tích hợp Chatbox AI | F1: Kết thúc đúng hạn
A2: Module name: | C2: Sprint 3 | F2: Muộn
A3: Start date: | C3: 22/04/2026 | F3: Trước thời hạn
A4: End date: | C4: 46208
B6: SPRINT 3 REPORT
B7: No | C7: Thành viên | D7: Thực tế | E7: Ước tính
B8: 1 | C8: Nguyễn Công Thành | D8: =SUMIF($E$16:$F$89,"Thành",$G$16:$G$89) +SUMIF($E$16:$F$89,"All team",$G$16:$G$89)/5 +SUMIF($E$16:$F$89,"Thành, Phương, Việt, Tấn",$G$16:$G$89)/4 -> 47.5 | E8: =SUMIF($E$16:$F$89,"Thành",$H$16:$H$89) +SUMIF($E$16:$F$89,"All team",$H$16:$H$89)/5 +SUMIF($E$16:$F$89,"Thành, Phương, Việt, Tấn",$H$16:$H$89)/4 -> 48.5
B9: 2 | C9: Nhan Thị Ngọc Nữ | D9: =SUMIF($E$16:$F$89,"Nữ",$G$16:$G$89) +SUMIF($E$16:$F$89,"All team",$G$16:$G$89)/5 -> 83 | E9: =SUMIF($E$16:$F$89,"Nữ",$H$16:$H$89) +SUMIF($E$16:$F$89,"All team",$H$16:$H$89)/5 -> 83
B10: 3 | C10: Đinh Thị Phương | D10: =SUMIF($E$16:$F$89,"Phương",$G$16:$G$89) +SUMIF($E$16:$F$89,"All team",$G$16:$G$89)/5 +SUMIF($E$16:$F$89,"Thành, Phương, Việt, Tấn",$G$16:$G$89)/4 -> 48.5 | E10: =SUMIF($E$16:$F$89,"Phương",$H$16:$H$89) +SUMIF($E$16:$F$89,"All team",$H$16:$H$89)/5 +SUMIF($E$16:$F$89,"Thành, Phương, Việt, Tấn",$H$16:$H$89)/4 -> 48.5
B11: 4 | C11: Nguyễn Quốc Tấn | D11: =SUMIF($E$16:$F$89,"Tấn",$G$16:$G$89) +SUMIF($E$16:$F$89,"All team",$G$16:$G$89)/5 +SUMIF($E$16:$F$89,"Thành, Phương, Việt, Tấn",$G$16:$G$89)/4 -> 47.5 | E11: =SUMIF($E$16:$F$89,"Tấn",$H$16:$H$89) +SUMIF($E$16:$F$89,"All team",$H$16:$H$89)/5 +SUMIF($E$16:$F$89,"Thành, Phương, Việt, Tấn",$H$16:$H$89)/4 -> 47.5
B12: 5 | C12: Phan Hồ Phi Việt | D12: =SUMIF($E$16:$F$89,"Việt",$G$16:$G$89) +SUMIF($E$16:$F$89,"All team",$G$16:$G$89)/5 +SUMIF($E$16:$F$89,"Thành, Phương, Việt, Tấn",$G$16:$G$89)/4 -> 48.5 | E12: =SUMIF($E$16:$F$89,"Việt",$H$16:$H$89) +SUMIF($E$16:$F$89,"All team",$H$16:$H$89)/5 +SUMIF($E$16:$F$89,"Thành, Phương, Việt, Tấn",$H$16:$H$89)/4 -> 48.5
B13: Tổng | D13: =SUM(D8:D12) -> 275 | E13: =SUM(E8:E12) -> 276
A15: Sprint | B15: Compoment | C15: Task name | E15: Responsible Member | G15: Thực tế | H15: Ước tính | I15: 46134 | J15: 46135 | K15: 46136 | L15: 46137 | M15: 46138 | N15: 46139 | O15: 46140 | P15: 46141 | Q15: 46142 | R15: 46143 | S15: 46144 | T15: 46145 | U15: 46146 | V15: 46147 | W15: 46148 | X15: 46149
A16: Sprint 3 | B16: Họp kế hoạch Sprint | E16: All team | G16: 5 | H16: 5 | I16: 5 | J16: 0 | K16: 0 | L16: 0 | M16: 0 | N16: 0 | O16: 0 | P16: 0 | Q16: 0 | R16: 0 | S16: 0 | T16: 0 | U16: 0 | V16: 0 | W16: 0 | X16: 0
B17: Tạo Sprint Backlog 3 | E17: Việt, Phương | G17: 6 | H17: 5 | I17: 5 | J17: 0 | K17: 0 | L17: 0 | M17: 0 | N17: 0 | O17: 0 | P17: 0 | Q17: 0 | R17: 0 | S17: 0 | T17: 0 | U17: 0 | V17: 0 | W17: 0 | X17: 0
J18: 1 | K18: 0 | L18: 0 | M18: 0 | N18: 0 | O18: 0 | P18: 0 | Q18: 0 | R18: 0 | S18: 0 | T18: 0 | U18: 0 | V18: 0 | W18: 0 | X18: 0
B19: Tạo tài liệu kiểm thử cho Sprint | E19: Nữ | G19: 2 | H19: 2 | I19: 2 | J19: 0 | K19: 0 | L19: 0 | M19: 0 | N19: 0 | O19: 0 | P19: 0 | Q19: 0 | R19: 0 | S19: 0 | T19: 0 | U19: 0 | V19: 0 | W19: 0 | X19: 0
B20: User interface design | C20: Giao diện tìm kiếm | E20: Nữ | G20: 2 | H20: 2 | I20: 2 | J20: 0 | K20: 0 | L20: 0 | M20: 0 | N20: 0 | O20: 0 | P20: 0 | Q20: 0 | R20: 0 | S20: 0 | T20: 0 | U20: 0 | V20: 0 | W20: 0 | X20: 0
C21: Giao diện xem chi tiết sản phẩm | E21: Nữ | G21: 2 | H21: 2 | I21: 2 | J21: 0 | K21: 0 | L21: 0 | M21: 0 | N21: 0 | O21: 0 | P21: 0 | Q21: 0 | R21: 0 | S21: 0 | T21: 0 | U21: 0 | V21: 0 | W21: 0 | X21: 0
C22: Giao diện giỏ hàng | E22: Nữ | G22: 1 | H22: 1 | I22: 1 | J22: 0 | K22: 0 | L22: 0 | M22: 0 | N22: 0 | O22: 0 | P22: 0 | Q22: 0 | R22: 0 | S22: 0 | T22: 0 | U22: 0 | V22: 0 | W22: 0 | X22: 0
C23: Giao diện thanh toán | E23: Nữ | G23: 1 | H23: 1 | I23: 1 | J23: 1 | K23: 0 | L23: 0 | M23: 0 | N23: 0 | O23: 0 | P23: 0 | Q23: 0 | R23: 0 | S23: 0 | T23: 0 | U23: 0 | V23: 0 | W23: 0 | X23: 0
C24: Giao diện quên mật khẩu | E24: Nữ | G24: 1 | H24: 1 | I24: 1 | J24: 1 | K24: 0 | L24: 0 | M24: 0 | N24: 0 | O24: 0 | P24: 0 | Q24: 0 | R24: 0 | S24: 0 | T24: 0 | U24: 0 | V24: 0 | W24: 0 | X24: 0
C25: Giao diện chatbot | E25: Nữ | G25: 1 | H25: 1 | I25: 1 | J25: 1 | K25: 0 | L25: 0 | M25: 0 | N25: 0 | O25: 0 | P25: 0 | Q25: 0 | R25: 0 | S25: 0 | T25: 0 | U25: 0 | V25: 0 | W25: 0 | X25: 0
C26: Giao diện thêm sản phẩm vào giỏ hàng | E26: Nữ | G26: 2 | H26: 1 | I26: 1 | J26: 1 | K26: 0 | L26: 0 | M26: 0 | N26: 0 | O26: 0 | P26: 0 | Q26: 0 | R26: 0 | S26: 0 | T26: 0 | U26: 0 | V26: 0 | W26: 0 | X26: 0
K27: 1 | L27: 0 | M27: 0 | N27: 0 | O27: 0 | P27: 0 | Q27: 0 | R27: 0 | S27: 0 | T27: 0 | U27: 0 | V27: 0 | W27: 0 | X27: 0
C28: Giao diện mua hàng | E28: Nữ | G28: 1 | H28: 1 | I28: 1 | J28: 1 | K28: 1 | L28: 0 | M28: 0 | N28: 0 | O28: 0 | P28: 0 | Q28: 0 | R28: 0 | S28: 0 | T28: 0 | U28: 0 | V28: 0 | W28: 0 | X28: 0
C29: Review all user interfaces of sprint 2 | E29: All team | G29: 5 | H29: 5 | I29: 5 | J29: 5 | K29: 5 | L29: 0 | M29: 0 | N29: 0 | O29: 0 | P29: 0 | Q29: 0 | R29: 0 | S29: 0 | T29: 0 | U29: 0 | V29: 0 | W29: 0 | X29: 0
B30: Design test case | C30: Thiết kế trường kiểm thử cho tìm kiếm | E30: Thành | G30: 1 | H30: 1 | I30: 1 | J30: 1 | K30: 1 | L30: 0 | M30: 0 | N30: 0 | O30: 0 | P30: 0 | Q30: 0 | R30: 0 | S30: 0 | T30: 0 | U30: 0 | V30: 0 | W30: 0 | X30: 0
C31: Thiết kế trường kiểm thử cho xem chi tiết sản phẩm | E31: Tấn | G31: 1 | H31: 1 | I31: 1 | J31: 1 | K31: 1 | L31: 0 | M31: 0 | N31: 0 | O31: 0 | P31: 0 | Q31: 0 | R31: 0 | S31: 0 | T31: 0 | U31: 0 | V31: 0 | W31: 0 | X31: 0
C32: Thiết kế trường kiểm thử cho giỏ hàng | E32: Phương | G32: 1 | H32: 1 | I32: 1 | J32: 1 | K32: 1 | L32: 0 | M32: 0 | N32: 0 | O32: 0 | P32: 0 | Q32: 0 | R32: 0 | S32: 0 | T32: 0 | U32: 0 | V32: 0 | W32: 0 | X32: 0
C33: Thiết kế trường kiểm thử cho thanh toán | E33: Tấn | G33: 2 | H33: 1 | I33: 1 | J33: 1 | K33: 1 | L33: 0 | M33: 0 | N33: 0 | O33: 0 | P33: 0 | Q33: 0 | R33: 0 | S33: 0 | T33: 0 | U33: 0 | V33: 0 | W33: 0 | X33: 0
L34: 1 | M34: 0 | N34: 0 | O34: 0 | P34: 0 | Q34: 0 | R34: 0 | S34: 0 | T34: 0 | U34: 0 | V34: 0 | W34: 0 | X34: 0
C35: Thiết kế trường kiểm thử cho quên mật khẩu | E35: Việt | G35: 1 | H35: 1 | I35: 1 | J35: 1 | K35: 1 | L35: 1 | M35: 0 | N35: 0 | O35: 0 | P35: 0 | Q35: 0 | R35: 0 | S35: 0 | T35: 0 | U35: 0 | V35: 0 | W35: 0 | X35: 0
C36: Thiết kế trường kiểm thử cho chatbot | E36: Thành | G36: 1 | H36: 2 | I36: 2 | J36: 2 | K36: 2 | L36: 2 | M36: 0 | N36: 0 | O36: 0 | P36: 0 | Q36: 0 | R36: 0 | S36: 0 | T36: 0 | U36: 0 | V36: 0 | W36: 0 | X36: 0
M37: 1 | N37: 0 | O37: 0 | P37: 0 | Q37: 0 | R37: 0 | S37: 0 | T37: 0 | U37: 0 | V37: 0 | W37: 0 | X37: 0
C38: Thiết kế trường kiểm thử cho thêm sản phẩm vào giỏ hàng | E38: Phương | G38: 2 | H38: 2 | I38: 2 | J38: 2 | K38: 2 | L38: 2 | M38: 2 | N38: 0 | O38: 0 | P38: 0 | Q38: 0 | R38: 0 | S38: 0 | T38: 0 | U38: 0 | V38: 0 | W38: 0 | X38: 0
C39: Thiết kế trường kiểm thử cho mua hàng | E39: Việt | G39: 2 | H39: 2 | I39: 2 | J39: 2 | K39: 2 | L39: 2 | M39: 2 | N39: 0 | O39: 0 | P39: 0 | Q39: 0 | R39: 0 | S39: 0 | T39: 0 | U39: 0 | V39: 0 | W39: 0 | X39: 0
C40: Review all test case of sprint 1 | E40: All team | G40: 5 | H40: 5 | I40: 5 | J40: 5 | K40: 5 | L40: 5 | M40: 5 | N40: 0 | O40: 0 | P40: 0 | Q40: 0 | R40: 0 | S40: 0 | T40: 0 | U40: 0 | V40: 0 | W40: 0 | X40: 0
B41: Coding | C41: Thiết kê front-end tìm kiếm | E41: Thành | G41: 6 | H41: 6 | I41: 6 | J41: 6 | K41: 6 | L41: 6 | M41: 6 | N41: 0 | O41: 0 | P41: 0 | Q41: 0 | R41: 0 | S41: 0 | T41: 0 | U41: 0 | V41: 0 | W41: 0 | X41: 0
C42: Code back-end tìm kiếm | E42: Thành | G42: 6 | H42: 6 | I42: 6 | J42: 6 | K42: 6 | L42: 6 | M42: 6 | N42: 0 | O42: 0 | P42: 0 | Q42: 0 | R42: 0 | S42: 0 | T42: 0 | U42: 0 | V42: 0 | W42: 0 | X42: 0
...

Sheet Total
A1: SPRINT BACKLOG REPORT
B2: Thành | D2: Nữ | F2: Phương | H2: Tấn | J2: Việt
B3: Thực tế | C3: Ước tính | D3: Thực tế | E3: Ước tính | F3: Thực tế | G3: Ước tính | H3: Thực tế | I3: Ước tính | J3: Thực tế | K3: Ước tính
A4: Sprint 1 | B4: ='Sprint 1'!$D$8 -> 34.25 | C4: ='Sprint 1'!$E$8 -> 39.25 | D4: ='Sprint 1'!$D$9 -> 54 | E4: ='Sprint 1'!$E$9 -> 52 | F4: ='Sprint 1'!$D$10 -> 29.25 | G4: ='Sprint 1'!$E$10 -> 25.25 | H4: ='Sprint 1'!$D$11 -> 19.25 | I4: ='Sprint 1'!$E$11 -> 19.25 | J4: ='Sprint 1'!$D$12 -> 39.25 | K4: ='Sprint 1'!$E$12 -> 37.25
A5: Sprint 2 | B5: ='Sprint 2'!$D$8 -> 58.25 | C5: ='Sprint 2'!$E$8 -> 59.25 | D5: ='Sprint 2'!$D$9 -> 58 | E5: ='Sprint 2'!$E$9 -> 56 | F5: ='Sprint 2'!$D$10 -> 50.25 | G5: ='Sprint 2'!$E$10 -> 49.25 | H5: ='Sprint 2'!$D$11 -> 54.25 | I5: ='Sprint 2'!$E$11 -> 54.25 | J5: ='Sprint 2'!$D$12 -> 22.25 | K5: ='Sprint 2'!$E$12 -> 22.25
A6: Sprint 3 | B6: ='Sprint 3'!$D$8 -> 47.5 | C6: ='Sprint 3'!$E$8 -> 48.5 | D6: ='Sprint 3'!$D$9 -> 83 | E6: ='Sprint 3'!$E$9 -> 83 | F6: ='Sprint 3'!$D$10 -> 48.5 | G6: ='Sprint 3'!$E$10 -> 48.5 | H6: ='Sprint 3'!$D$11 -> 47.5 | I6: ='Sprint 3'!$E$11 -> 47.5 | J6: ='Sprint 3'!$D$12 -> 48.5 | K6: ='Sprint 3'!$E$12 -> 48.5
A7: Tổng | B7: =SUM(B4:B6) -> 140 | C7: =SUM(C4:C6) -> 147 | D7: =SUM(D4:D6) -> 195 | E7: =SUM(E4:E6) -> 191 | F7: =SUM(F4:F6) -> 128 | G7: =SUM(G4:G6) -> 123 | H7: =SUM(H4:H6) -> 121 | I7: =SUM(I4:I6) -> 121 | ... K7: =SUM(K4:K6) -> 108
E10: FINAL TOTAL
E11: Thực tế | F11: =SUMIF($B$3:$K$3,"Thực tế",$B$7:$K$7) -> 694
E12: Ước tính | F12: =SUMIF($B$3:$K$3,"Ước tính",$B$7:$K$7) -> 690
