Workbook

Sheet Trường hợp kiểm thử
D2: TEST CASE SYSTEM SPRINT 1
D4: Tên dự án | E4: Xây dựng hệ thống thương mại điện tử mỹ phẩm Hamoni cosmetic tích hợp Chatbox AI.
D5: STT | E5: Chức năng | F5: Sheet Name | G5: Số lượng test | H5: Mô tả
D6: 1 | E6: Quản lý kho | F6: Danh sách cập nhật tồn kho | G6: 38 | H6: Nữ
F7: Phiếu xuất kho | G7: 31
F8: Phiếu nhập kho | G8: 31
D9: 2 | E9: Quản lý khuyến mãi | F9: Danh sách mã khuyến mãi | G9: 25
F10: Thêm mã Khuyến mãi | G10: 35
F11: Cập nhật mã khuyến mãi | G11: 19
D12: 3 | E12: Quản lý voucher | F12: Danh sách và thêm voucher | G12: 31
F13: Cập nhật voucher | G13: 28
D14: 4 | E14: Quản lý đơn hàng | F14: Danh sách đơn hàng | G14: 26
F15: Chi tiết đơn hàng | G15: 28
F16: In hoá đơn | G16: 28
F17: Lịch sử đơn hàng | G17: 15
D18: 5 | E18: Quản lý đánh giá | F18: Danh sách đánh giá | G18: 39
F19: Chi tiết đánh giá | G19: 19
D20: 6 | E20: Quản lý chatbot | F20: Quản lý chatbot | G20: 20
D21: 7 | E21: Xem chi tiết đơn hàng | F21: Xem chi tiết đơn hàng | G21: 32
D22: 8 | E22: Xem lịch sử đơn hàng | F22: Xem lịch sử đơn hàng | G22: 24
D23: 9 | E23: Thống kê báo cáo | F23: Thống kê báo cáo | G23: 22
D24: 10 | E24: Đánh giá sản phẩm | F24: Đánh giá sản phẩm | G24: 15
G25: =SUM(G6:H24) -> 506

Sheet Danh sách cập nhật tồn kho
A1: Project Name | B1: XÂY DỰNG HỆ THỐNG THƯƠNG MẠI ĐIỆN TỬ MỸ PHẨM HAMONI COSMETIC VÀ CHATBOX AI TƯ VẤN KHÁCH HÀNG
A2: Module Code | B2: Danh sách cập nhật tồn kho
B3: Hoàn thành | C3: Lỗi | D3: Chưa kiểm tra | E3: Bị chăn | F3: Tổng số trường hợp thử nghiệm
A4: Round 1 | B4: 38 | C4: 0 | D4: =COUNTIF('Phiếu nhập kho'!G11:G21,"Untested") -> 0 | E4: =COUNTIF('Phiếu nhập kho'!G11:G21,"Blocked") -> 0 | F4: 38
A5: Round 2 | B5: 0 | C5: 0 | D5: =COUNTIF('Phiếu nhập kho'!J11:J21,"Untested") -> 0 | E5: =COUNTIF('Phiếu nhập kho'!J11:J21,"Blocked") -> 0 | F5: 0
A36: Test Case ID | B36: Mô tả | C36: Qui trình | D36: Điều kiện tiên quyết | E36: Kết quả mong đợi | F36: Kết quả thực tế | G36: Kết quả | J36: Kết quả | M36: Chú thích
G37: Vòng 1 | J37: Vòng 2
G38: Trạng thái | H38: Ngày kiểm tra | I38: Người kiểm tra | J38: Trạng thái | K38: Ngày kiểm tra | L38: Người kiểm tra
A39: GUI_SHOW Trang Danh sách cập nhật tồn kho
A40: GUI-DSCNTK01 | B40: [Title] TỰ ĐỘNG CẬP NHẬT TỒN KHO | E40: - Text: Black - Status: Enable | F40: - Text: Black - Status: Enable | G40: Passed | H40: 17/04/2026 | I40: Nữ
A41: GUI-DSCNTK02 | B41: [Button] Làm mới dữ liệu | E41: - Text: Black - Status: Enable | F41: - Text: Black - Status: Enable | G41: Passed | H41: 17/04/2026 | I41: Nữ
A42: GUI-DSCNTK03 | B42: [Card] Tổng sản phẩm | E42: - Text: Black - Status: Enable | F42: - Text: Black - Status: Enable | G42: Passed | H42: 17/04/2026 | I42: Nữ
A43: GUI-DSCNTK04 | B43: [Card] Sắp hết | E43: - Text: Black - Status: Enable | F43: - Text: Black - Status: Enable | G43: Passed | H43: 17/04/2026 | I43: Nữ
A44: GUI-DSCNTK05 | B44: [Card] Hết hàng | E44: - Text: Black - Status: Enable | F44: - Text: Black - Status: Enable | G44: Passed | H44: 17/04/2026 | I44: Nữ
A45: GUI-DSCNTK06 | B45: [Card] Cập nhật gần nhất | E45: - Text: Black - Status: Enable | F45: - Text: Black - Status: Enable | G45: Passed | H45: 17/04/2026 | I45: Nữ
A46: GUI-DSCNTK07 | B46: [Table] Bảng theo dõi tồn kho | E46: - Text: Black - Status: Enable | F46: - Text: Black - Status: Enable | G46: Passed | H46: 17/04/2026 | I46: Nữ
A47: GUI-DSCNTK08 | B47: [Column] Sản phẩm | E47: - Text: Black - Status: Enable | F47: - Text: Black - Status: Enable | G47: Passed | H47: 17/04/2026 | I47: Nữ
A48: GUI-DSCNTK09 | B48: [Column] Hiện có | E48: - Text: Black - Status: Enable | F48: - Text: Black - Status: Enable | G48: Passed | H48: 17/04/2026 | I48: Nữ
A49: GUI-DSCNTK10 | B49: [Column] Trạng thái | E49: - Text: Black - Status: Enable | F49: - Text: Black - Status: Enable | G49: Passed | H49: 17/04/2026 | I49: Nữ
A50: GUI-DSCNTK11 | B50: [Column] Biến động | E50: - Text: Black - Status: Enable | F50: - Text: Black - Status: Enable | G50: Passed | H50: 17/04/2026 | I50: Nữ
A51: GUI-DSCNTK12 | B51: [Column] Thời gian | E51: - Text: Black - Status: Enable | F51: - Text: Black - Status: Enable | G51: Passed | H51: 17/04/2026 | I51: Nữ
... A57: GUI-DSCNTK18 | B57: [Button] Nhập Kho | E57: - Text: Black - Status: Enable | F57: - Text: Black - Status: Enable | G57: Passed | H57: 17/04/2026 | I57: Nữ
A58: FUNCTION_SHOW Trang Danh sách cập nhật tồn kho
A59: FUNC-DSCNTK01 | B59: Kiểm tra hiển thị danh sách tồn kho | C59: 1. Mở trang tồn kho. 2. Quan sát danh sách sản phẩm. | D59: Đăng nhập vào hệ thống | E59: Hệ thống hiển thị đầy đủ dữ liệu | F59: Hệ thống hiển thị đầy đủ dữ liệu | G59: Passed | H59: 17/04/2026 | I59: Nữ
A60: FUNC-DSCNTK02 | B60: Kiểm tra tổng số sản phẩm | C60: 1. Mở dashboard tồn kho. 2. Kiểm tra card tổng sản phẩm. | D60: Đăng nhập vào hệ thống | E60: Hiển thị đúng sản phẩm | F60: Hiển thị đúng sản phẩm | G60: Passed | H60: 17/04/2026 | I60: Nữ
A61: FUNC-DSCNTK03 | B61: Kiểm tra trạng thái sắp hết | C61: 1. Set số lượng tồn từ 1-10. 2. Reload trang. | D61: Đăng nhập vào hệ thống | E61: Hiển thị đúng trạng thái | F61: Hiển thị đúng trạng thái | G61: Passed | H61: 17/04/2026 | I61: Nữ
A62: FUNC-DSCNTK04 | B62: Kiểm tra trạng thái hết hàng | C62: 1. Set tồn kho bằng 0. 2. Reload trang. | D62: Đăng nhập vào hệ thống | E62: Hiển thị đúng trạng thái | F62: Hiển thị đúng trạng thái | G62: Passed | H62: 17/04/2026 | I62: Nữ
A63: FUNC-DSCNTK05 | B63: Kiểm tra cập nhật thời gian realtime | C63: 1. Reload dữ liệu. 2. Quan sát thời gian cập nhật. | D63: Đăng nhập vào hệ thống | E63: Thời gian được cập nhật mới | F63: Thời gian được cập nhật mới | G63: Passed | H63: 17/04/2026 | I63: Nữ
A64: FUNC-DSCNTK06 | B64: Kiểm tra nút “Làm mới dữ liệu” | C64: 1. Click button “Làm mới dữ liệu”. 2. Quan sát dữ liệu sau refresh. | D64: Đăng nhập vào hệ thống | E64: Dữ liệu refresh thành công | F64: Dữ liệu refresh thành công | G64: Passed | H64: 17/04/2026 | I64: Nữ
A65: FUNC-DSCNTK07 | B65: Kiểm tra hiển thị số lượng tồn | C65: 1. Load danh sách sản phẩm. 2. So sánh số lượng với DB. | D65: Đăng nhập vào hệ thống | E65: Hiển thị đúng dữ liệu | F65: Hiển thị đúng dữ liệu | G65: Passed | H65: 17/04/2026 | I65: Nữ
A66: FUNC-DSCNTK08 | B66: Kiểm tra trạng thái “Sẵn sàng” | C66: 1. Set tồn kho > 10. 2. Reload trang. | D66: Đăng nhập vào hệ thống | E66: Hiển thị đúng badge màu xanh | F66: Hiển thị đúng badge màu xanh | G66: Passed | H66: 17/04/2026 | I66: Nữ
A67: FUNC-DSCNTK09 | B67: Kiểm tra phân trang | C67: 1. Click sang trang 2. 2. Click quay lại trang 1. | D67: Đăng nhập vào hệ thống | E67: Chuyển trang thành công | F67: Chuyển trang thành công | G67: Passed | H67: 17/04/2026 | I67: Nữ
A68: FUNC-DSCNTK10 | B68: Kiểm tra tìm kiếm nhật ký | C68: 1. Nhập từ khóa sản phẩm. 2. Click tìm kiếm. | D68: Đăng nhập vào hệ thống | E68: Kết quả hiển thị chính xác | F68: Kết quả hiển thị chính xác | G68: Passed | H68: 17/04/2026 | I68: Nữ
A69: FUNC-DSCNTK11 | B69: Kiểm tra log nhập kho | C69: 1. Thực hiện nhập kho. 2. Kiểm tra nhật ký tự động. | D69: Đăng nhập vào hệ thống | E69: Log hiển thị đúng thông tin | F69: Log hiển thị đúng thông tin | G69: Passed | H69: 17/04/2026 | I69: Nữ
A70: FUNC-DSCNTK12 | B70: Kiểm tra log xuất kho | C70: 1. Thực hiện xuất kho. 2. Kiểm tra nhật ký tự động. | D70: Đăng nhập vào hệ thống | E70: Log hiển thị đúng thông tin | F70: Log hiển thị đúng thông tin | G70: Passed | H70: 17/04/2026 | I70: Nữ
... A78: FUNC-DSCNTK20 | B78: Kiểm tra realtime nhiều user | C78: 1. User A nhập kho. 2. User B reload dữ liệu. | D78: Đăng nhập vào hệ thống | E78: Dữ liệu cập nhật đúng realtime | F78: Dữ liệu cập nhật đúng realtime | G78: Passed | H78: 17/04/2026 | I78: Nữ

Sheet Phiếu xuất kho
A1: Project Name | B1: XÂY DỰNG HỆ THỐNG THƯƠNG MẠI ĐIỆN TỬ MỸ PHẨM HAMONI COSMETIC VÀ CHATBOX AI TƯ VẤN KHÁCH HÀNG
A2: Module Code | B2: Phiếu xuất kho
B3: Hoàn thành | C3: Lỗi | D3: Chưa kiểm tra | E3: Bị chăn | F3: Tổng số trường hợp thử nghiệm
A4: Round 1 | B4: 31 | C4: 0 | D4: =COUNTIF('Phiếu nhập kho'!G11:G21,"Untested") -> 0 | E4: =COUNTIF('Phiếu nhập kho'!G11:G21,"Blocked") -> 0 | F4: 31
A5: Round 2 | B5: 0 | C5: 0 | D5: =COUNTIF('Phiếu nhập kho'!J11:J21,"Untested") -> 0 | E5: =COUNTIF('Phiếu nhập kho'!J11:J21,"Blocked") -> 0 | F5: 0
A35: Test Case ID | B35: Mô tả | C35: Qui trình | D35: Điều kiện tiên quyết | E35: Kết quả mong đợi | F35: Kết quả thực tế | G35: Kết quả | J35: Kết quả | M35: Chú thích
G36: Vòng 1 | J36: Vòng 2
G37: Trạng thái | H37: Ngày kiểm tra | I37: Người kiểm tra | J37: Trạng thái | K37: Ngày kiểm tra | L37: Người kiểm tra
A38: GUI_SHOW Trang Phiếu xuất kho
A39: GUI-PXK01 | B39: [Title] XUẤT KHO | E39: - Text: Black - Status: Enable | F39: - Text: Black - Status: Enable | G39: Passed | H39: 17/04/2026 | I39: Nữ
A40: GUI-PXK02 | B40: [Dropdown] Loại nghiệp vụ | E40: - Text: Black - Status: Enable | F40: - Text: Black - Status: Enable | G40: Passed | H40: 17/04/2026 | I40: Nữ
A41: GUI-PXK03 | B41: [Placeholder] -- Loại xuất -- | E41: - Text: Black - Status: Enable | F41: - Text: Black - Status: Enable | G41: Passed | H41: 17/04/2026 | I41: Nữ
A42: GUI-PXK04 | B42: [Textarea] Ghi chú | E42: - Text: Black - Status: Enable | F42: - Text: Black - Status: Enable | G42: Passed | H42: 17/04/2026 | I42: Nữ
A43: GUI-PXK05 | B43: [Section] Danh sách sản phẩm | E43: - Text: Black - Status: Enable | F43: - Text: Black - Status: Enable | G43: Passed | H43: 17/04/2026 | I43: Nữ
A44: GUI-PXK06 | B44: Column] Sản phẩm | E44: - Text: Black - Status: Enable | F44: - Text: Black - Status: Enable | G44: Passed | H44: 17/04/2026 | I44: Nữ
A45: GUI-PXK07 | B45: [Column] Số lượng | E45: - Text: Black - Status: Enable | F45: - Text: Black - Status: Enable | G45: Passed | H45: 17/04/2026 | I45: Nữ
A46: GUI-PXK08 | B46: [Column] Tồn kho | E46: - Text: Black - Status: Enable | F46: - Text: Black - Status: Enable | G46: Passed | H46: 17/04/2026 | I46: Nữ
A47: GUI-PXK09 | B47: [Input] Tìm sản phẩm | E47: - Text: Black - Status: Enable | F47: - Text: Black - Status: Enable | G47: Passed | H47: 17/04/2026 | I47: Nữ
A48: GUI-PXK10 | B48: [Input] Số lượng xuất | E48: - Text: Black - Status: Enable | F48: - Text: Black - Status: Enable | G48: Passed | H48: 17/04/2026 | I48: Nữ
A49: GUI-PXK11 | B49: [Button] Xóa sản phẩm | E49: - Text: Black - Status: Enable | F49: - Text: Black - Status: Enable | G49: Passed | H49: 17/04/2026 | I49: Nữ
A50: GUI-PXK12 | B50: [Button] + Thêm sản phẩm | E50: - Text: Black - Status: Enable | F50: - Text: Black - Status: Enable | G50: Passed | H50: 17/04/2026 | I50: Nữ
A51: GUI-PXK13 | B51: [Button] Xác nhận | E51: - Text: Black - Status: Enable | F51: - Text: Black - Status: Enable | G51: Passed | H51: 17/04/2026 | I51: Nữ
A52: FUNCTION_SHOW Trang Phiếu xuất kho
A53: FUNC-PXK01 | B53: Kiểm tra hiển thị form xuất kho | C53: 1. Mở trang xuất kho. 2. Quan sát giao diện form. | D53: Đăng nhập vào hệ thống | E53: Hệ thống hiển thị đầy đủ form xuất kho | F53: Hệ thống hiển thị đầy đủ form xuất kho | G53: Passed | H53: 17/04/2026 | I53: Nữ
A54: FUNC-PXK02 | B54: Kiểm tra dropdown loại nghiệp vụ | C54: 1. Click dropdown loại xuất. 2. Quan sát danh sách lựa chọn. | D54: Đăng nhập vào hệ thống | E54: Hiển thị đúng dữ liệu | F54: Hiển thị đúng dữ liệu | G54: Passed | H54: 17/04/2026 | I54: Nữ
A55: FUNC-PXK03 | B55: Kiểm tra validate bắt buộc loại xuất | C55: 1. Không chọn loại xuất. 2. Click “Xác nhận”. | D55: Đăng nhập vào hệ thống | E55: Hệ thống hiển thị cảnh báo bắt buộc chọn | F55: Hệ thống hiển thị cảnh báo bắt buộc chọn | G55: Passed | H55: 17/04/2026 | I55: Nữ
A56: FUNC-PXK04 | B56: Kiểm tra nhập ghi chú | C56: 1. Nhập nội dung ghi chú. 2. Click ra ngoài textarea. | D56: Đăng nhập vào hệ thống | E56: Hệ thống lưu đúng nội dung nhập | F56: Hệ thống lưu đúng nội dung nhập | G56: Passed | H56: 17/04/2026 | I56: Nữ
A57: FUNC-PXK05 | B57: Kiểm tra tìm kiếm sản phẩm | C57: 1. Nhập tên sản phẩm. 2. Quan sát kết quả gợi ý. | D57: Đăng nhập vào hệ thống | E57: Hiển thị đúng sản phẩm liên quan | F57: Hiển thị đúng sản phẩm liên quan | G57: Passed | H57: 17/04/2026 | I57: Nữ
A58: FUNC-PXK06 | B58: Kiểm tra thêm sản phẩm | C58: 1. Click “+ Thêm sản phẩm”. 2. Quan sát dòng sản phẩm mới. | D58: Đăng nhập vào hệ thống | E58: Hệ thống thêm dòng nhập sản phẩm mới | F58: Hệ thống thêm dòng nhập sản phẩm mới | G58: Passed | H58: 17/04/2026 | I58: Nữ
A59: FUNC-PXK07 | B59: Kiểm tra xóa sản phẩm | C59: 1. Click nút “X”. 2. Quan sát danh sách sản phẩm. | D59: Đăng nhập vào hệ thống | E59: Dòng sản phẩm được xóa khỏi danh sách | F59: Dòng sản phẩm được xóa khỏi danh sách | G59: Passed | H59: 17/04/2026 | I59: Nữ
A60: FUNC-PXK08 | B60: Kiểm tra nhập số lượng xuất | C60: 1. Nhập số lượng sản phẩm. 2. Click ra ngoài input. | D60: Đăng nhập vào hệ thống | E60: Hệ thống nhận đúng giá trị số lượng | F60: Hệ thống nhận đúng giá trị số lượng | G60: Passed | H60: 17/04/2026 | I60: Nữ
A61: FUNC-PXK09 | B61: Kiểm tra validate số lượng âm | C61: 1. Nhập số lượng âm. 2. Click “Xác nhận”. | D61: Đăng nhập vào hệ thống | E61: Không cho phép nhập số âm | F61: Không cho phép nhập số âm | G61: Passed | H61: 17/04/2026 | I61: Nữ
A62: FUNC-PXK10 | B62: Kiểm tra xuất vượt tồn kho | C62: 1. Nhập số lượng lớn hơn tồn kho. 2. Click “Xác nhận”. | D62: Đăng nhập vào hệ thống | E62: Hệ thống chặn xuất vượt tồn | F62: Hệ thống chặn xuất vượt tồn | G62: Passed | H62: 17/04/2026 | I62: Nữ
A63: FUNC-PXK11 | B63: Kiểm tra hiển thị tồn kho | C63: 1. Chọn sản phẩm. 2. Quan sát cột tồn kho. | D63: Đăng nhập vào hệ thống | E63: Hiển thị đúng số lượng tồn kho | F63: Hiển thị đúng số lượng tồn kho | G63: Passed | H63: 17/04/2026 | I63: Nữ
A64: FUNC-PXK12 | B64: Kiểm tra xác nhận xuất kho | C64: 1. Nhập đầy đủ thông tin. 2. Click “Xác nhận”. | D64: Đăng nhập vào hệ thống | E64: Hệ thống tạo phiếu xuất kho thành công | F64: Hệ thống tạo phiếu xuất kho thành công | G64: Passed | H64: 17/04/2026 | I64: Nữ
... A70: FUNC-PXK18 | B70: Kiểm tra load lại trang | C70: 1. Reload trình duyệt. 2. Quan sát dữ liệu form. | D70: Đăng nhập vào hệ thống | E70: Form được reset dữ liệu | F70: Form được reset dữ liệu | G70: Passed | H70: 17/04/2026 | I70: Nữ

Sheet Phiếu nhập kho
A1: Project Name | B1: XÂY DỰNG HỆ THỐNG THƯƠNG MẠI ĐIỆN TỬ MỸ PHẨM HAMONI COSMETIC VÀ CHATBOX AI TƯ VẤN KHÁCH HÀNG
A2: Module Code | B2: Phiếu nhập kho
B3: Hoàn thành | C3: Lỗi | D3: Chưa kiểm tra | E3: Bị chăn | F3: Tổng số trường hợp thử nghiệm
A4: Round 1 | B4: 31 | C4: 0 | D4: =COUNTIF('Phiếu nhập kho'!G11:G21,"Untested") -> 0 | E4: =COUNTIF('Phiếu nhập kho'!G11:G21,"Blocked") -> 0 | F4: 31
A5: Round 2 | B5: 0 | C5: 0 | D5: =COUNTIF('Phiếu nhập kho'!J11:J21,"Untested") -> 0 | E5: =COUNTIF('Phiếu nhập kho'!J11:J21,"Blocked") -> 0 | F5: 0
A29: Test Case ID | B29: Mô tả | C29: Qui trình | D29: Điều kiện tiên quyết | E29: Kết quả mong đợi | F29: Kết quả thực tế | G29: Kết quả | J29: Kết quả | M29: Chú thích
G30: Vòng 1 | J30: Vòng 2
G31: Trạng thái | H31: Ngày kiểm tra | I31: Người kiểm tra | J31: Trạng thái | K31: Ngày kiểm tra | L31: Người kiểm tra
A32: GUI_SHOW Trang Phiếu nhập kho
A33: GUI-PNK01 | B33: [Title] NHẬP KHO | E33: - Text: Black - Status: Enable | F33: - Text: Black - Status: Enable | G33: Passed | H33: 17/04/2026 | I33: Nữ
A34: GUI-PNK02 | B34: [Dropdown] Loại nghiệp vụ | E34: - Text: Black - Status: Enable | F34: - Text: Black - Status: Enable | G34: Passed | H34: 17/04/2026 | I34: Nữ
A35: GUI-PNK03 | B35: [Placeholder] -- Loại nhập -- | E35: - Text: Black - Status: Enable | F35: - Text: Black - Status: Enable | G35: Passed | H35: 17/04/2026 | I35: Nữ
A36: GUI-PNK04 | B36: [Textarea] Ghi chú | E36: - Text: Black - Status: Enable | F36: - Text: Black - Status: Enable | G36: Passed | H36: 17/04/2026 | I36: Nữ
A37: GUI-PNK05 | B37: [Section] Danh sách sản phẩm | E37: - Text: Black - Status: Enable | F37: - Text: Black - Status: Enable | G37: Passed | H37: 17/04/2026 | I37: Nữ
A38: GUI-PNK06 | B38: Column] Sản phẩm | E38: - Text: Black - Status: Enable | F38: - Text: Black - Status: Enable | G38: Passed | H38: 17/04/2026 | I38: Nữ
A39: GUI-PNK07 | B39: [Column] Số lượng | E39: - Text: Black - Status: Enable | F39: - Text: Black - Status: Enable | G39: Passed | H39: 17/04/2026 | I39: Nữ
A40: GUI-PNK08 | B40: [Column] Tồn kho | E40: - Text: Black - Status: Enable | F40: - Text: Black - Status: Enable | G40: Passed | H40: 17/04/2026 | I40: Nữ
A41: GUI-PNK09 | B41: [Input] Tìm sản phẩm | E41: - Text: Black - Status: Enable | F41: - Text: Black - Status: Enable | G41: Passed | H41: 17/04/2026 | I41: Nữ
A42: GUI-PNK10 | B42: [Input] Số lượng nhập | E42: - Text: Black - Status: Enable | F42: - Text: Black - Status: Enable | G42: Passed | H42: 17/04/2026 | I42: Nữ
A43: GUI-PNK11 | B43: [Button] Xóa sản phẩm | E43: - Text: Black - Status: Enable | F43: - Text: Black - Status: Enable | G43: Passed | H43: 17/04/2026 | I43: Nữ
A44: GUI-PNK12 | B44: [Button] + Thêm sản phẩm | E44: - Text: Black - Status: Enable | F44: - Text: Black - Status: Enable | G44: Passed | H44: 17/04/2026 | I44: Nữ
... A46: GUI-PNK14 | B46: [Button] Xác nhận | E46: - Text: Black - Status: Enable | F46: - Text: Black - Status: Enable | G46: Passed | H46: 17/04/2026 | I46: Nữ
A47: FUNCTION_SHOW Trang Phiếu nhập kho
A48: FUNC-PNK01 | B48: Kiểm tra hiển thị form nhập kho | C48: 1. Mở trang nhậpt kho. 2. Quan sát giao diện form. | D48: Đăng nhập vào hệ thống | E48: Hệ thống hiển thị đầy đủ form nhập kho | F48: Hệ thống hiển thị đầy đủ form nhập kho | G48: Passed | H48: 17/04/2026 | I48: Nữ
A49: FUNC-PNK02 | B49: Kiểm tra dropdown loại nghiệp vụ | C49: 1. Click dropdown loại xuất. 2. Quan sát danh sách lựa chọn. | D49: Đăng nhập vào hệ thống | E49: Hiển thị đúng dữ liệu | F49: Hiển thị đúng dữ liệu | G49: Passed | H49: 17/04/2026 | I49: Nữ
A50: FUNC-PNK03 | B50: Kiểm tra validate bắt buộc loại nhập | C50: 1. Không chọn loại nhập. 2. Click “Xác nhận”. | D50: Đăng nhập vào hệ thống | E50: Hệ thống hiển thị cảnh báo bắt buộc chọn | F50: Hệ thống hiển thị cảnh báo bắt buộc chọn | G50: Passed | H50: 17/04/2026 | I50: Nữ
A51: FUNC-PNK04 | B51: Kiểm tra nhập ghi chú | C51: 1. Nhập nội dung ghi chú. 2. Click ra ngoài textarea. | D51: Đăng nhập vào hệ thống | E51: Hệ thống lưu đúng nội dung nhập | F51: Hệ thống lưu đúng nội dung nhập | G51: Passed | H51: 17/04/2026 | I51: Nữ
A52: FUNC-PNK05 | B52: Kiểm tra tìm kiếm sản phẩm | C52: 1. Nhập tên sản phẩm. 2. Quan sát kết quả gợi ý. | D52: Đăng nhập vào hệ thống | E52: Hiển thị đúng sản phẩm liên quan | F52: Hiển thị đúng sản phẩm liên quan | G52: Passed | H52: 17/04/2026 | I52: Nữ
A53: FUNC-PNK06 | B53: Kiểm tra thêm sản phẩm | C53: 1. Click “+ Thêm sản phẩm”. 2. Quan sát dòng sản phẩm mới. | D53: Đăng nhập vào hệ thống | E53: Hệ thống thêm dòng nhập sản phẩm mới | F53: Hệ thống thêm dòng nhập sản phẩm mới | G53: Passed | H53: 17/04/2026 | I53: Nữ
A54: FUNC-PNK07 | B54: Kiểm tra xóa sản phẩm | C54: 1. Click nút “X”. 2. Quan sát danh sách sản phẩm. | D54: Đăng nhập vào hệ thống | E54: Dòng sản phẩm được xóa khỏi danh sách | F54: Dòng sản phẩm được xóa khỏi danh sách | G54: Passed | H54: 17/04/2026 | I54: Nữ
A55: FUNC-PNK08 | B55: Kiểm tra nhập số lượng nhập | C55: 1. Nhập số lượng sản phẩm. 2. Click ra ngoài input. | D55: Đăng nhập vào hệ thống | E55: Hệ thống nhận đúng giá trị số lượng | F55: Hệ thống nhận đúng giá trị số lượng | G55: Passed | H55: 17/04/2026 | I55: Nữ
A56: FUNC-PNK09 | B56: Kiểm tra validate số lượng âm | C56: 1. Nhập số lượng âm. 2. Click “Xác nhận”. | D56: Đăng nhập vào hệ thống | E56: Không cho phép nhập số âm | F56: Không cho phép nhập số âm | G56: Passed | H56: 17/04/2026 | I56: Nữ
A57: FUNC-PNK10 | B57: Kiểm tra hiển thị tồn kho | C57: 1. Chọn sản phẩm. 2. Quan sát cột tồn kho. | D57: Đăng nhập vào hệ thống | E57: Hiển thị đúng số lượng tồn kho | F57: Hiển thị đúng số lượng tồn kho | G57: Passed | H57: 17/04/2026 | I57: Nữ
A58: FUNC-PNK11 | B58: Kiểm tra xác nhận nhập kho | C58: 1. Nhập đầy đủ thông tin. 2. Click “Xác nhận”. | D58: Đăng nhập vào hệ thống | E58: Hệ thống tạo phiếu nhập kho thành công | F58: Hệ thống tạo phiếu nhập kho thành công | G58: Passed | H58: 17/04/2026 | I58: Nữ
A59: FUNC-PNK12 | B59: Kiểm tra dữ liệu rỗng | C59: 1. Không nhập dữ liệu. 2. Click “Xác nhận”. | D59: Đăng nhập vào hệ thống | E59: Hiển thị thông báo bắt buộc nhập dữ liệu | F59: Hiển thị thông báo bắt buộc nhập dữ liệu | G59: Passed | H59: 17/04/2026 | I59: Nữ
... A64: FUNC-PNK17 | B64: Kiểm tra load lại trang | C64: 1. Reload trình duyệt. 2. Quan sát dữ liệu form. | D64: Đăng nhập vào hệ thống | E64: Form được reset dữ liệu | F64: Form được reset dữ liệu | G64: Passed | H64: 17/04/2026 | I64: Nữ

Sheet Danh sách mã khuyến mãi
A1: Project Name | B1: XÂY DỰNG HỆ THỐNG THƯƠNG MẠI ĐIỆN TỬ MỸ PHẨM HAMONI COSMETIC VÀ CHATBOX AI TƯ VẤN KHÁCH HÀNG
A2: Module Code | B2: Danh sách mã khuyến mãi
B3: Hoàn thành | C3: Lỗi | D3: Chưa kiểm tra | E3: Bị chăn | F3: Tổng số trường hợp thử nghiệm
A4: Round 1 | B4: 24 | C4: 1 | D4: =COUNTIF('Phiếu nhập kho'!G11:G21,"Untested") -> 0 | E4: =COUNTIF('Phiếu nhập kho'!G11:G21,"Blocked") -> 0 | F4: 25
A5: Round 2 | B5: 25 | C5: 0 | D5: =COUNTIF('Phiếu nhập kho'!J11:J21,"Untested") -> 0 | E5: =COUNTIF('Phiếu nhập kho'!J11:J21,"Blocked") -> 0 | F5: 25
A25: Test Case ID | B25: Mô tả | C25: Qui trình | D25: Điều kiện tiên quyết | E25: Kết quả mong đợi | F25: Kết quả thực tế | G25: Kết quả | J25: Kết quả | M25: Chú thích
G26: Vòng 1 | J26: Vòng 2
G27: Trạng thái | H27: Ngày kiểm tra | I27: Người kiểm tra | J27: Trạng thái | K27: Ngày kiểm tra | L27: Người kiểm tra
A28: GUI_SHOW Trang danh sách mã khuyến mãi
A29: GUI-DSMKM01 | B29: [Title] QUẢN LÝ CHƯƠNG TRÌNH SALE | E29: - Text: Black - Status: Enable | F29: - Text: Black - Status: Enable | G29: Passed | H29: 17/04/2026 | I29: Nữ
A30: GUI-DSMKM02 | B30: [Button] Tạo khuyến mãi mới | E30: - Text: Black - Status: Enable | F30: - Text: Black - Status: Enable | G30: Passed | H30: 17/04/2026 | I30: Nữ
A31: GUI-DSMKM03 | B31: [Table] Danh sách chương trình | E31: - Text: Black - Status: Enable | F31: - Text: Black - Status: Enable | G31: Passed | H31: 17/04/2026 | I31: Nữ
A32: GUI-DSMKM04 | B32: [Column] Tên chương trình | E32: - Text: Black - Status: Enable | F32: - Text: Black - Status: Enable | G32: Passed | H32: 17/04/2026 | I32: Nữ
A33: GUI-DSMKM05 | B33: [Column] Mức giảm | E33: - Text: Black - Status: Enable | F33: - Text: Black - Status: Enable | G33: Passed | H33: 17/04/2026 | I33: Nữ
A34: GUI-DSMKM06 | B34: [Column] Thời gian | E34: - Text: Black - Status: Enable | F34: - Text: Black - Status: Enable | G34: Passed | H34: 17/04/2026 | I34: Nữ
A35: GUI-DSMKM07 | B35: [Column] Trạng thái | E35: - Text: Black - Status: Enable | F35: - Text: Black - Status: Enable | G35: Passed | H35: 17/04/2026 | I35: Nữ
A36: GUI-DSMKM08 | B36: [Status] Chưa diễn ra | E36: - Text: Black - Status: Enable | F36: - Text: Black - Status: Enable | G36: Passed | H36: 17/04/2026 | I36: Nữ
A37: GUI-DSMKM09 | B37: [Status] Đang hoạt động | E37: - Text: Black - Status: Enable | F37: - Text: Black - Status: Enable | G37: Passed | H37: 17/04/2026 | I37: Nữ
A38: GUI-DSMKM10 | B38: [Status] Đã hết hạn | E38: - Text: Black - Status: Enable | F38: - Text: Black - Status: Enable | G38: Passed | H38: 17/04/2026 | I38: Nữ
A39: GUI-DSMKM11 | B39: [Sort icon] Trạng thái | E39: - Text: Black - Status: Enable | F39: - Text: Black - Status: Enable | G39: Passed | H39: 17/04/2026 | I39: Nữ
A40: FUNCTION_SHOW Trang danh sách mã khuyến mãi
A41: FUNC-DSMKM01 | B41: Kiểm tra hiển thị danh sách | C41: 1. Mở trang sale | D41: Đăng nhập vào hệ thống | E41: Hệ thống hiển thị danh sách chương trình từ DB | F41: Hệ thống hiển thị danh sách chương trình từ DB | G41: Passed | H41: 17/04/2026 | I41: Nữ
A42: FUNC-DSMKM02 | B42: Kiểm tra trạng thái "Chưa diễn ra" | C42: 1. So sánh thời gian hiện tại < start date | D42: Đăng nhập vào hệ thống | E42: Hiển thị trạng thái "Chưa diễn ra" | F42: Hiển thị trạng thái "Chưa diễn ra" | G42: Passed | H42: 17/04/2026 | I42: Nữ
A43: FUNC-DSMKM03 | B43: Kiểm tra trạng thái "Đang hoạt động" | C43: 1. So sánh start <= current <= end | D43: Đăng nhập vào hệ thống | E43: Hiển thị "Đang hoạt động" | F43: Hiển thị "Đang hoạt động" | G43: Passed | H43: 17/04/2026 | I43: Nữ
A44: FUNC-DSMKM04 | B44: Kiểm tra trạng thái "Đã hết hạn" | C44: 1. So sánh current > end | D44: Đăng nhập vào hệ thống | E44: Hiển thị "Đã hết hạn" | F44: Hiển thị "Đã hết hạn" | G44: Passed | H44: 17/04/2026 | I44: Nữ
A45: FUNC-DSMKM05 | B45: Kiểm tra format mức giảm % | C45: 1. Tạo data giảm % | D45: Đăng nhập vào hệ thống | E45: Hiển thị dạng "-10%" | F45: Hiển thị dạng "-10%" | G45: Passed | H45: 17/04/2026 | I45: Nữ
A46: FUNC-DSMKM06 | B46: Kiểm tra format mức giảm tiền | C46: 1. Tạo data giảm tiền | D46: Đăng nhập vào hệ thống | E46: Hiển thị "-10,000đ" | F46: Hiển thị "-10,000đ" | G46: Passed | H46: 17/04/2026 | I46: Nữ
A47: FUNC-DSMKM07 | B47: Kiểm tra thời gian hiển thị | C47: 1. Load dữ liệu | D47: Đăng nhập vào hệ thống | E47: Hiển thị đúng format datetime | F47: Hiển thị đúng format datetime | G47: Passed | H47: 17/04/2026 | I47: Nữ
A48: FUNC-DSMKM08 | B48: Kiểm tra sort trạng thái | C48: 1. Click icon sort | D48: Đăng nhập vào hệ thống | E48: Danh sách được sắp xếp theo trạng thái | F48: Danh sách được sắp xếp theo trạng thái | G48: Passed | H48: 17/04/2026 | I48: Nữ
A49: FUNC-DSMKM09 | B49: Kiểm tra click "Tạo khuyến mãi" | C49: 1. Click button | D49: Đăng nhập vào hệ thống | E49: Điều hướng sang form tạo mới | F49: Điều hướng sang form tạo mới | G49: Passed | H49: 17/04/2026 | I49: Nữ
A50: FUNC-DSMKM10 | B50: Kiểm tra dữ liệu trùng tên | C50: 1. Có 2 chương trình cùng tên | D50: Đăng nhập vào hệ thống | E50: Hệ thống vẫn hiển thị bình thường | F50: Hệ thống vẫn hiển thị bình thường | G50: Passed | H50: 17/04/2026 | I50: Nữ
A51: FUNC-DSMKM11 | B51: Kiểm tra khoảng thời gian lỗi | C51: 1. Thời gian bắt đầu > thời gian kết thúc | D51: Đăng nhập vào hệ thống | E51: Không cho hiển thị hoặc báo lỗi | F51: ❌ Vẫn hiển thị | G51: Failed | H51: 17/04/2026 | I51: Nữ | J51: Passed | K51: 18/04/2026 | L51: Nữ
A52: FUNC-DSMKM12 | B52: Kiểm tra timezone | C52: 1. Set giờ khác timezone | D52: Đăng nhập vào hệ thống | E52: Trạng thái vẫn đúng logic | F52: Trạng thái vẫn đúng logic | G52: Passed | H52: 17/04/2026 | I52: Nữ
A53: FUNC-DSMKM13 | B53: Kiểm tra dữ liệu rỗng | C53: 1. Không có chương trình | D53: Đăng nhập vào hệ thống | E53: Hiển thị "Không có dữ liệu" | F53: Hiển thị "Không có dữ liệu" | G53: Passed | H53: 17/04/2026 | I53: Nữ
A54: FUNC-DSMKM14 | B54: Kiểm tra refresh data | C54: 1. Reload trang | D54: Đăng nhập vào hệ thống | E54: Dữ liệu cập nhật mới | F54: Dữ liệu cập nhật mới | G54: Passed | H54: 17/04/2026 | I54: Nữ

Sheet Thêm mã khuyến mãi
A1: Project Name | B1: XÂY DỰNG HỆ THỐNG THƯƠNG MẠI ĐIỆN TỬ MỸ PHẨM HAMONI COSMETIC VÀ CHATBOX AI TƯ VẤN KHÁCH HÀNG
A2: Module Code | B2: Thêm mã khuyến mãi
B3: Hoàn thành | C3: Lỗi | D3: Chưa kiểm tra | E3: Bị chăn | F3: Tổng số trường hợp thử nghiệm
A4: Round 1 | B4: 31 | C4: 4 | D4: =COUNTIF('Phiếu nhập kho'!G11:G21,"Untested") -> 0 | E4: =COUNTIF('Phiếu nhập kho'!G11:G21,"Blocked") -> 0 | F4: 35
A5: Round 2 | B5: 31 | C5: 0 | D5: =COUNTIF('Phiếu nhập kho'!J11:J21,"Untested") -> 0 | E5: =COUNTIF('Phiếu nhập kho'!J11:J21,"Blocked") -> 0 | F5: 35
A32: Test Case ID | B32: Mô tả | C32: Qui trình | D32: Điều kiện tiên quyết | E32: Kết quả mong đợi | F32: Kết quả thực tế | G32: Kết quả | J32: Kết quả | M32: Chú thích
G33: Vòng 1 | J33: Vòng 2
G34: Trạng thái | H34: Ngày kiểm tra | I34: Người kiểm tra | J34: Trạng thái | K34: Ngày kiểm tra | L34: Người kiểm tra
A35: GUI_SHOW Trang Thêm mã khuyến mãi
A36: GUI-TMKM01 | B36: [Title] TẠO CHƯƠNG TRÌNH SALE MỚI | E36: - Text: Black - Status: Enable | F36: - Text: Black - Status: Enable | G36: Passed | H36: 18/04/2026 | I36: Nữ
A37: GUI-TMKM02 | B37: [Input] Tên chương trình | E37: - Text: Black - Status: Enable | F37: - Text: Black - Status: Enable | G37: Passed | H37: 18/04/2026 | I37: Nữ
A38: GUI-TMKM03 | B38: [Dropdown] Loại giảm giá | E38: - Text: Black - Status: Enable | F38: - Text: Black - Status: Enable | G38: Passed | H38: 18/04/2026 | I38: Nữ
A39: GUI-TMKM04 | B39: [Input] Mức giảm | E39: - Text: Black - Status: Enable | F39: - Text: Black - Status: Enable | G39: Passed | H39: 18/04/2026 | I39: Nữ
A40: GUI-TMKM05 | B40: [Date] Ngày bắt đầu | E40: - Text: Black - Status: Enable | F40: - Text: Black - Status: Enable | G40: Passed | H40: 18/04/2026 | I40: Nữ
A41: GUI-TMKM06 | B41: [Date] Ngày kết thúc | E41: - Text: Black - Status: Enable | F41: - Text: Black - Status: Enable | G41: Passed | H41: 18/04/2026 | I41: Nữ
A42: GUI-TMKM07 | B42: [Search] Tìm kiếm sản phẩm | E42: - Text: Black - Status: Enable | F42: - Text: Black - Status: Enable | G42: Passed | H42: 18/04/2026 | I42: Nữ
A43: GUI-TMKM08 | B43: [List] Danh sách sản phẩm | E43: - Text: Black - Status: Enable | F43: - Text: Black - Status: Enable | G43: Passed | H43: 18/04/2026 | I43: Nữ
A44: GUI-TMKM09 | B44: [Checkbox] Chọn sản phẩm | E44: - Text: Black - Status: Enable | F44: - Text: Black - Status: Enable | G44: Passed | H44: 18/04/2026 | I44: Nữ
A45: GUI-TMKM10 | B45: [Button] Bỏ chọn tất cả | E45: - Text: Black - Status: Enable | F45: - Text: Black - Status: Enable | G45: Passed | H45: 18/04/2026 | I45: Nữ
A46: GUI-TMKM11 | B46: [Button] Hủy bỏ | E46: - Text: Black - Status: Enable | F46: - Text: Black - Status: Enable | G46: Passed | H46: 18/04/2026 | I46: Nữ
A47: GUI-TMKM12 | B47: [Button] Lưu chương trình | E47: - Text: Black - Status: Enable | F47: - Text: Black - Status: Enable | G47: Passed | H47: 18/04/2026 | I47: Nữ
A48: FUNCTION_SHOW Trang thêm mã khuyến mãi
A49: FUNC-TMKM01 | B49: Kiểm tra tạo sale hợp lệ | C49: 1. Nhập đầy đủ thông tin 2. Chọn sản phẩm 3. Click "Lưu chương trình" | D49: Đăng nhập vào hệ thống | E49: Hệ thống tạo thành công, hiển thị thông báo | F49: Hệ thống tạo thành công, hiển thị thông báo | G49: Passed | H49: 18/04/2026 | I49: Nữ
A50: FUNC-TMKM02 | B50: Kiểm tra bỏ trống tên | C50: 1. Không nhập tên 2. Click "Lưu" | D50: Đăng nhập vào hệ thống | E50: Hiển thị lỗi "Tên chương trình là bắt buộc" | F50: Hiển thị lỗi "Tên chương trình là bắt buộc" | G50: Passed | H50: 18/04/2026 | I50: Nữ
A51: FUNC-TMKM03 | B51: Kiểm tra bỏ trống mức giảm | C51: 1. Không nhập mức giảm 2. Lưu | D51: Đăng nhập vào hệ thống | E51: Hiển thị lỗi bắt buộc | F51: Hiển thị lỗi bắt buộc | G51: Passed | H51: 18/04/2026 | I51: Nữ
A52: FUNC-TMKM04 | B52: Kiểm tra mức giảm âm | C52: 1. Nhập -10 2. Lưu | D52: Đăng nhập vào hệ thống | E52: Báo lỗi "Mức giảm phải > 0" | F52: Lưu thành công | G52: Failed | H52: 18/04/2026 | I52: Nữ | J52: Passed | K52: 18/04/2026 | L52: Nữ
A53: FUNC-TMKM05 | B53: Kiểm tra mức giảm = 0 | C53: 1. Nhập 0 2. Lưu | D53: Đăng nhập vào hệ thống | E53: Báo lỗi không hợp lệ | F53: Lưu thành công | G53: Failed | H53: 18/04/2026 | I53: Nữ | J53: Passed | K53: 18/04/2026 | L53: Nữ
A54: FUNC-TMKM06 | B54: Kiểm tra % > 100 | C54: 1. Nhập 150% 2. Lưu | D54: Đăng nhập vào hệ thống | E54: Báo lỗi vượt quá 100% | F54: Lưu thành công | G54: Failed | H54: 18/04/2026 | I54: Nữ | J54: Passed | K54: 18/04/2026 | L54: Nữ
A55: FUNC-TMKM07 | B55: Kiểm tra thời gian hợp lệ | C55: 1. Start < End 2. Lưu | D55: Đăng nhập vào hệ thống | E55: Lưu thành công | G55: Passed | H55: 18/04/2026 | I55: Nữ
A56: FUNC-TMKM08 | B56: Kiểm tra start > end | C56: 1. Start > End 2. Lưu | D56: Đăng nhập vào hệ thống | E56: Báo lỗi thời gian | F56: Lưu thành công | G56: Failed | H56: 18/04/2026 | I56: Nữ | J56: Passed | K56: 18/04/2026 | L56: Nữ
A57: FUNC-TMKM09 | B57: Kiểm tra không chọn sản phẩm | C57: 1. Không chọn SP 2. Lưu | D57: Đăng nhập vào hệ thống | E57: Báo lỗi yêu cầu chọn sản phẩm | F57: Báo lỗi yêu cầu chọn sản phẩm | G57: Passed | H57: 18/04/2026 | I57: Nữ
A58: FUNC-TMKM10 | B58: Kiểm tra chọn nhiều sản phẩm | C58: 1. Tick nhiều checkbox 2. Lưu | D58: Đăng nhập vào hệ thống | E58: Lưu tất cả sản phẩm vào sale | F58: Lưu tất cả sản phẩm vào sale | G58: Passed | H58: 18/04/2026 | I58: Nữ
A59: FUNC-TMKM11 | B59: Kiểm tra bỏ chọn tất cả | C59: 1. Chọn nhiều SP 2. Click "Bỏ chọn tất cả" | D59: Đăng nhập vào hệ thống | E59: Tất cả checkbox bị bỏ chọn | F59: Tất cả checkbox bị bỏ chọn | G59: Passed | H59: 18/04/2026 | I59: Nữ
A60: FUNC-TMKM12 | B60: Kiểm tra search sản phẩm | C60: 1. Nhập keyword 2. Quan sát | D60: Đăng nhập vào hệ thống | E60: Filter đúng sản phẩm | F60: Filter đúng sản phẩm | G60: Passed | H60: 18/04/2026 | I60: Nữ
A61: FUNC-TMKM13 | B61: Kiểm tra search không có kết quả | C61: 1. Nhập text không tồn tại | D61: Đăng nhập vào hệ thống | E61: Hiển thị "Không có sản phẩm" | F61: Hiển thị "Không có sản phẩm" | G61: Passed | H61: 18/04/2026 | I61: Nữ
A62: FUNC-TMKM14 | B62: Kiểm tra ký tự đặc biệt tên | C62: 1. Nhập ***@@@ 2. Lưu | D62: Đăng nhập vào hệ thống | E62: Validate hoặc báo lỗi | F62: Validate hoặc báo lỗi | G62: Passed | H62: 18/04/2026 | I62: Nữ
A63: FUNC-TMKM15 | B63: Kiểm tra lưu khi mất mạng | C63: 1. Tắt mạng 2. Click lưu | D63: Đăng nhập vào hệ thống | E63: Hiển thị lỗi hệ thống | F63: Hiển thị lỗi hệ thống | G63: Passed | H63: 18/04/2026 | I63: Nữ
A64: FUNC-TMKM16 | B64: Kiểm tra nút Hủy khi chưa nhập dữ liệu | C64: 1. Mở form 2. Click "Hủy bỏ" | D64: Đăng nhập vào hệ thống | E64: Quay về đúng trang danh sách, không phát sinh dữ liệu | F64: Quay về đúng trang danh sách, không phát sinh dữ liệu | G64: Passed | H64: 18/04/2026 | I64: Nữ
A65: FUNC-TMKM17 | B65: Kiểm tra nút Hủy khi đã nhập dữ liệu | C65: 1. Nhập dữ liệu bất kỳ 2. Click "Hủy bỏ" | D65: Đăng nhập vào hệ thống | E65: Quay về đúng trang danh sách, không phát sinh dữ liệu | F65: Quay về đúng trang danh sách, không phát sinh dữ liệu | G65: Passed | H65: 18/04/2026 | I65: Nữ
A66: FUNC-TMKM18 | B66: Kiểm tra lưu hợp lệ | C66: 1. Nhập đầy đủ thông tin hợp lệ 2. Click "Lưu chương trình" | D66: Đăng nhập vào hệ thống | E66: Lưu thành công | F66: Lưu thành công | G66: Passed | H66: 18/04/2026 | I66: Nữ
...

Sheet Cập nhật mã khuyến mãi
A1: Project Name | B1: XÂY DỰNG HỆ THỐNG THƯƠNG MẠI ĐIỆN TỬ MỸ PHẨM HAMONI COSMETIC VÀ CHATBOX AI TƯ VẤN KHÁCH HÀNG
A2: Module Code | B2: Cập nhật mã khuyến mãi
B3: Hoàn thành | C3: Lỗi | D3: Chưa kiểm tra | E3: Bị chăn | F3: Tổng số trường hợp thử nghiệm
A4: Round 1 | B4: 15 | C4: 4 | D4: =COUNTIF('Phiếu nhập kho'!G11:G21,"Untested") -> 0 | E4: =COUNTIF('Phiếu nhập kho'!G11:G21,"Blocked") -> 0 | F4: 19
A5: Round 2 | B5: 19 | C5: 0 | D5: =COUNTIF('Phiếu nhập kho'!J11:J21,"Untested") -> 0 | E5: =COUNTIF('Phiếu nhập kho'!J11:J21,"Blocked") -> 0 | F5: 19
A34: Test Case ID | B34: Mô tả | C34: Qui trình | D34: Điều kiện tiên quyết | E34: Kết quả mong đợi | F34: Kết quả thực tế | G34: Kết quả | J34: Kết quả | M34: Chú thích
G35: Vòng 1 | J35: Vòng 2
G36: Trạng thái | H36: Ngày kiểm tra | I36: Người kiểm tra | J36: Trạng thái | K36: Ngày kiểm tra | L36: Người kiểm tra
A37: GUI_SHOW Trang cập nhật mã khuyến mãi
A38: GUI-CNMKM01 | B38: [Title] CHI TIẾT: LỄ HỘI 30/4 | E38: - Text: Black - Status: Enable | F38: - Text: Black - Status: Enable | G38: Passed | H38: 18/04/2026 | I38: Nữ
A39: GUI-CNMKM02 | B39: Input Tên chương trình | E39: - Text: Black - Status: Enable | F39: - Text: Black - Status: Enable | G39: Passed | H39: 18/04/2026 | I39: Nữ
A40: GUI-CNMKM03 | B40: Dropdown Loại giảm | E40: - Text: Black - Status: Enable | F40: - Text: Black - Status: Enable | G40: Passed | H40: 18/04/2026 | I40: Nữ
A41: GUI-CNMKM04 | B41: Input Giá trị giảm | E41: - Text: Black - Status: Enable | F41: - Text: Black - Status: Enable | G41: Passed | H41: 18/04/2026 | I41: Nữ
A42: GUI-CNMKM05 | B42: DateTime Bắt đầu/Kết thúc | E42: - Text: Black - Status: Enable | F42: - Text: Black - Status: Enable | G42: Passed | H42: 18/04/2026 | I42: Nữ
A43: GUI-CNMKM06 | B43: Danh sách sản phẩm | E43: - Text: Black - Status: Enable | F43: - Text: Black - Status: Enable | G43: Passed | H43: 18/04/2026 | I43: Nữ
A44: GUI-CNMKM07 | B44: Checkbox sản phẩm | E44: - Text: Black - Status: Enable | F44: - Text: Black - Status: Enable | G44: Passed | H44: 18/04/2026 | I44: Nữ
A45: GUI-CNMKM08 | B45: Nút LƯU THAY ĐỔI | E45: - Text: Black - Status: Enable | F45: - Text: Black - Status: Enable | G45: Passed | H45: 18/04/2026 | I45: Nữ
A46: GUI-CNMKM09 | B46: Nút XÓA CHƯƠNG TRÌNH | E46: - Text: Black - Status: Enable | F46: - Text: Black - Status: Enable | G46: Passed | H46: 18/04/2026 | I46: Nữ
A47: FUNCTION_SHOW Trang cập nhật mã khuyến mãi
A48: FUNC-CNMKM01 | B48: Kiểm tra lưu chỉnh sửa hợp lệ | C48: 1. Sửa dữ liệu 2. Click "Lưu thay đổi" | D48: Đăng nhập vào hệ thống | E48: Lưu thành công, cập nhật dữ liệu | F48: Lưu thành công, cập nhật dữ liệu | G48: Passed | H48: 18/04/2026 | I48: Nữ
A49: FUNC-TMKM02 | B49: Kiểm tra lưu khi không thay đổi dữ liệu | C49: 1. Không sửa 2. Click "Lưu" | D49: Đăng nhập vào hệ thống | E49: Không lỗi, giữ nguyên dữ liệu | F49: Không lỗi, giữ nguyên dữ liệu | G49: Passed | H49: 18/04/2026 | I49: Nữ
A50: FUNC-TMKM03 | B50: Kiểm tra lưu khi bỏ chọn tất cả sản phẩm | C50: 1. Uncheck toàn bộ 2. Click "Lưu" | D50: Đăng nhập vào hệ thống | E50: Không cho lưu, hiển thị lỗi | F50: Lưu thành công | G50: Failed | H50: 18/04/2026 | I50: Nữ | J50: Passed | K50: 18/04/2026 | L50: Nữ
A51: FUNC-TMKM04 | B51: Kiểm tra nhập giá trị không hợp lệ | C51: 1. Nhập chữ / âm 2. Lưu | D51: Đăng nhập vào hệ thống | E51: Hiển thị lỗi validate | F51: Lưu thành công | G51: Failed | H51: 18/04/2026 | I51: Nữ | J51: Passed | K51: 18/04/2026 | L51: Nữ
A52: FUNC-TMKM05 | B52: Kiểm tra ngày không hợp lệ | C52: 1. End < Start 2. Lưu | D52: Đăng nhập vào hệ thống | E52: Hiển thị lỗi ngày | F52: Lưu thành công | G52: Failed | H52: 18/04/2026 | I52: Nữ | J52: Passed | K52: 18/04/2026 | L52: Nữ
A53: FUNC-TMKM06 | B53: Kiểm tra chọn sản phẩm bằng checkbox | C53: 1. Tick checkbox | D53: Đăng nhập vào hệ thống | E53: Sản phẩm được chọn | F53: Sản phẩm được chọn | G53: Passed | H53: 18/04/2026 | I53: Nữ
A54: FUNC-TMKM07 | B54: Kiểm tra bỏ chọn sản phẩm | C54: 1. Untick checkbox | D54: Đăng nhập vào hệ thống | E54: Sản phẩm được chọn | F54: Sản phẩm được chọn | G54: Passed | H54: 18/04/2026 | I54: Nữ
A55: FUNC-TMKM08 | B55: Kiểm tra giới hạn số lượng sản phẩm | C55: 1. Chọn quá số lượng | D55: Đăng nhập vào hệ thống | E55: Không cho chọn thêm | F55: Được phép cho chọn thêm | G55: Failed | H55: 18/04/2026 | I55: Nữ | J55: Passed | K55: 18/04/2026 | L55: Nữ
A56: FUNC-TMKM09 | B56: Kiểm tra xóa chương trình | C56: 1. Click "Xóa" 2. Cancel | D56: Đăng nhập vào hệ thống | E56: Xóa thành công, quay về danh sách | F56: Xóa thành công, quay về danh sách | G56: Passed | H56: 18/04/2026 | I56: Nữ
A57: FUNC-TMKM10 | B57: Kiểm tra hủy thao tác xóa | C57: 1. Click "Xóa" 2. Cancel | D57: Đăng nhập vào hệ thống | E57: Không bị xóa | F57: Không bị xóa | G57: Passed | H57: 18/04/2026 | I57: Nữ

Sheet Danh sách và thêm voucher
A1: Project Name | B1: XÂY DỰNG HỆ THỐNG THƯƠNG MẠI ĐIỆN TỬ MỸ PHẨM HAMONI COSMETIC VÀ CHATBOX AI TƯ VẤN KHÁCH HÀNG
A2: Module Code | B2: Danh sách và thêm voucher
B3: Hoàn thành | C3: Lỗi | D3: Chưa kiểm tra | E3: Bị chăn | F3: Tổng số trường hợp thử nghiệm
A4: Round 1 | B4: 26 | C4: 5 | D4: =COUNTIF('Phiếu nhập kho'!G11:G21,"Untested") -> 0 | E4: =COUNTIF('Phiếu nhập kho'!G11:G21,"Blocked") -> 0 | F4: 31
A5: Round 2 | B5: 31 | C5: 0 | D5: =COUNTIF('Phiếu nhập kho'!J11:J21,"Untested") -> 0 | E5: =COUNTIF('Phiếu nhập kho'!J11:J21,"Blocked") -> 0 | F5: 31
A31: Test Case ID | B31: Mô tả | C31: Qui trình | D31: Điều kiện tiên quyết | E31: Kết quả mong đợi | F31: Kết quả thực tế | G31: Kết quả | J31: Kết quả | M31: Chú thích
G32: Vòng 1 | J32: Vòng 2
G33: Trạng thái | H33: Ngày kiểm tra | I33: Người kiểm tra | J33: Trạng thái | K33: Ngày kiểm tra | L33: Người kiểm tra
A34: GUI_SHOW Trang Danh sách và thêm voucher
A35: GUI-VOU01 | B35: [Title] Tạo Voucher Mới – hiển thị đúng | E35: - Text: Black - Status: Enable | F35: - Text: Black - Status: Enable | G35: Passed | H35: 18/04/2026 | I35: Nữ
A36: GUI-VOU02 | B36: [Input] Mã Voucher | E36: - Text: Black - Status: Enable | F36: - Text: Black - Status: Enable | G36: Passed | H36: 18/04/2026 | I36: Nữ
A37: GUI-VOU03 | B37: [Dropdown] Loại giảm giá | E37: - Text: Black - Status: Enable | F37: - Text: Black - Status: Enable | G37: Passed | H37: 18/04/2026 | I37: Nữ
A38: GUI-VOU04 | B38: [Input] Giá trị giảm | E38: - Text: Black - Status: Enable | F38: - Text: Black - Status: Enable | G38: Passed | H38: 18/04/2026 | I38: Nữ
A39: GUI-VOU05 | B39: [Input] SL phát hành | E39: - Text: Black - Status: Enable | F39: - Text: Black - Status: Enable | G39: Passed | H39: 18/04/2026 | I39: Nữ
A40: GUI-VOU06 | B40: [Input] Đơn tối thiểu | E40: - Text: Black - Status: Enable | F40: - Text: Black - Status: Enable | G40: Passed | H40: 18/04/2026 | I40: Nữ
A41: GUI-VOU07 | B41: [DatePicker] Ngày bắt đầu | E41: - Text: Black - Status: Enable | F41: - Text: Black - Status: Enable | G41: Passed | H41: 18/04/2026 | I41: Nữ
A42: GUI-VOU08 | B42: [DatePicker] Ngày kết thúc | E42: - Text: Black - Status: Enable | F42: - Text: Black - Status: Enable | G42: Passed | H42: 18/04/2026 | I42: Nữ
A43: GUI-VOU09 | B43: [Button] Tạo Mã Khuyến Mãi | E43: - Text: Black - Status: Enable | F43: - Text: Black - Status: Enable | G43: Passed | H43: 18/04/2026 | I43: Nữ
A44: GUI-VOU10 | B44: [Table] Danh sách voucher hiển thị | E44: - Text: Black - Status: Enable | F44: - Text: Black - Status: Enable | G44: Passed | H44: 18/04/2026 | I44: Nữ
A45: GUI-VOU11 | B45: [Column] Mã voucher | E45: - Text: Black - Status: Enable | F45: - Text: Black - Status: Enable | G45: Passed | H45: 18/04/2026 | I45: Nữ
A46: GUI-VOU12 | B46: [Column] Ưu đãi | E46: - Text: Black - Status: Enable | F46: - Text: Black - Status: Enable | G46: Passed | H46: 18/04/2026 | I46: Nữ
... A49: GUI-VOU15 | B49: [Tag] Trạng thái (Hoạt động / Hết hạn / Chưa diễn ra) | E49: - Text: Black - Status: Enable | F49: - Text: Black - Status: Enable | G49: Passed | H49: 18/04/2026 | I49: Nữ
A50: FUNCTION_SHOW Trang Danh sách và thêm voucher
A51: FUNC-VOU01 | B51: Kiểm tra tạo voucher hợp lệ | C51: 1. Nhập đầy đủ thông tin 2. Click "Tạo mã" | D51: Đăng nhập vào hệ thống | E51: Tạo thành công, hiển thị trong danh sách | F51: Tạo thành công, hiển thị trong danh sách | G51: Passed | H51: 18/04/2026 | I51: Nữ
A52: FUNC-VOU02 | B52: Kiểm tra bỏ trống mã voucher | C52: 1. Không nhập mã 2. Click tạo | D52: Đăng nhập vào hệ thống | E52: Hiển thị lỗi bắt buộc | F52: Hiển thị lỗi bắt buộc | G52: Passed | H52: 18/04/2026 | I52: Nữ
A53: FUNC-VOU03 | B53: Kiểm tra trùng mã voucher | C53: 1. Nhập mã đã tồn tại 2. Click tạo | D53: Đăng nhập vào hệ thống | E53: Báo lỗi trùng | F53: Báo lỗi trùng | G53: Passed | H53: 18/04/2026 | I53: Nữ
A54: FUNC-VOU04 | B54: Kiểm tra nhập giá trị giảm không hợp lệ | C54: 1. Nhập chữ 2. Click tạo | D54: Đăng nhập vào hệ thống | E54: Báo lỗi định dạng số | F54: Báo lỗi định dạng số | G54: Passed | H54: 18/04/2026 | I54: Nữ
A55: FUNC-VOU05 | B55: Kiểm tra % > 100 | C55: 1. Nhập 150% 2. Lưu | D55: Đăng nhập vào hệ thống | E55: Báo lỗi vượt giới hạn | F55: Lưu thành công | G55: Failed | H55: 18/04/2026 | I55: Nữ | J55: Passed | K55: 18/04/2026 | L55: Nữ
A56: FUNC-VOU06 | B56: Kiểm tra giá trị âm | C56: 1. Nhập -1000 2. Lưu | D56: Đăng nhập vào hệ thống | E56: Không cho lưu, báo lỗi | F56: Lưu thành công | G56: Failed | H56: 18/04/2026 | I56: Nữ | J56: Passed | K56: 18/04/2026 | L56: Nữ
A57: FUNC-VOU07 | B57: Kiểm tra số lượng phát hành âm | C57: 1. Nhập -1 | D57: Đăng nhập vào hệ thống | E57: Không cho lưu, báo lỗi | F57: Lưu thành công | G57: Failed | H57: 18/04/2026 | I57: Nữ | J57: Passed | K57: 18/04/2026 | L57: Nữ
A58: FUNC-VOU08 | B58: Kiểm tra ngày kết thúc < ngày bắt đầu | C58: 1. Chọn sai ngày | D58: Đăng nhập vào hệ thống | E58: Không cho lưu, báo lỗi | F58: Lưu thành công | G58: Failed | H58: 18/04/2026 | I58: Nữ | J58: Passed | K58: 18/04/2026 | L58: Nữ
A59: FUNC-VOU09 | B59: Kiểm tra bỏ trống ngày | C59: 1. Không chọn ngày | D59: Đăng nhập vào hệ thống | E59: Không cho lưu, báo lỗi | F59: Không cho lưu, báo lỗi | G59: Passed | H59: 18/04/2026 | I59: Nữ
A60: FUNC-VOU10 | B60: Kiểm tra đơn tối thiểu > 0 | C60: 1. Nhập 0 | D60: Đăng nhập vào hệ thống | E60: Tạo mã thành công | F60: Tạo mã thành công | G60: Passed | H60: 18/04/2026 | I60: Nữ
A61: FUNC-VOU11 | B61: Kiểm tra hiển thị danh sách | C61: 1. Vào trang | D61: Đăng nhập vào hệ thống | E61: Hiển thị đầy đủ danh sách, đúng ngày | F61: Hiển thị đầy đủ danh sách, sai ngày | G61: Failed | H61: 18/04/2026 | I61: Nữ | J61: Passed | K61: 18/04/2026 | L61: Nữ
A62: FUNC-VOU12 | B62: Kiểm tra trạng thái “Hoạt động” | C62: 1. Voucher trong thời gian | D62: Đăng nhập vào hệ thống | E62: Hiển thị "Hoạt động" | F62: Hiển thị "Hoạt động" | G62: Passed | H62: 18/04/2026 | I62: Nữ
A63: FUNC-VOU13 | B63: Kiểm tra trạng thái “Hết hạn” | C63: 1. Voucher quá hạn | D63: Đăng nhập vào hệ thống | E63: Hiển thị "Hết hạn" | F63: Hiển thị "Hết hạn" | G63: Passed | H63: 18/04/2026 | I63: Nữ
A64: FUNC-VOU14 | B64: Kiểm tra trạng thái “Chưa diễn ra” | C64: 1. Voucher chưa tới ngày | D64: Đăng nhập vào hệ thống | E64: Hiển thị đúng | F64: Hiển thị đúng | G64: Passed | H64: 18/04/2026 | I64: Nữ
A65: FUNC-VOU15 | B65: Kiểm tra format tiền | C65: 1. Xem ưu đãi | D65: Đăng nhập vào hệ thống | E65: Hiển thị đúng định dạng VNĐ | F65: Hiển thị đúng định dạng VNĐ | G65: Passed | H65: 18/04/2026 | I65: Nữ
A66: FUNC-VOU16 | B66: Kiểm tra cập nhật sau khi tạo mới | C66: 1. Tạo voucher 2. Quay lại list | D66: Đăng nhập vào hệ thống | E66: Hiển thị ngay | F66: Hiển thị ngay | G66: Passed | H66: 18/04/2026 | I66: Nữ

Sheet Cập nhật voucher
A1: Project Name | B1: XÂY DỰNG HỆ THỐNG THƯƠNG MẠI ĐIỆN TỬ MỸ PHẨM HAMONI COSMETIC VÀ CHATBOX AI TƯ VẤN KHÁCH HÀNG
A2: Module Code | B2: Cập nhật voucher
B3: Hoàn thành | C3: Lỗi | D3: Chưa kiểm tra | E3: Bị chăn | F3: Tổng số trường hợp thử nghiệm
A4: Round 1 | B4: 26 | C4: 2 | D4: =COUNTIF('Phiếu nhập kho'!G11:G21,"Untested") -> 0 | E4: =COUNTIF('Phiếu nhập kho'!G11:G21,"Blocked") -> 0 | F4: 28
A5: Round 2 | B5: 28 | C5: 0 | D5: =COUNTIF('Phiếu nhập kho'!J11:J21,"Untested") -> 0 | E5: =COUNTIF('Phiếu nhập kho'!J11:J21,"Blocked") -> 0 | F5: 28
A32: Test Case ID | B32: Mô tả | C32: Qui trình | D32: Điều kiện tiên quyết | E32: Kết quả mong đợi | F32: Kết quả thực tế | G32: Kết quả | J32: Kết quả | M32: Chú thích
G33: Vòng 1 | J33: Vòng 2
G34: Trạng thái | H34: Ngày kiểm tra | I34: Người kiểm tra | J34: Trạng thái | K34: Ngày kiểm tra | L34: Người kiểm tra
A35: GUI_SHOW Trang cập nhật voucher
A36: GUI-CNV01 | B36: [Title] Mã giảm giá: SIÊU SALE hiển thị đúng | E36: - Text: Black - Status: Enable | F36: - Text: Black - Status: Enable | G36: Passed | H36: 19/04/2026 | I36: Nữ
A37: GUI-CNV02 | B37: [Button] Quay lại hiển thị | E37: - Text: Black - Status: Enable | F37: - Text: Black - Status: Enable | G37: Passed | H37: 19/04/2026 | I37: Nữ
A38: GUI-CNV03 | B38: [Tag] Đã hết hạn | E38: - Text: Black - Status: Enable | F38: - Text: Black - Status: Enable | G38: Passed | H38: 19/04/2026 | I38: Nữ
A39: GUI-CNV04 | B39: [Input] Mã Voucher | E39: - Text: Black - Status: Enable | F39: - Text: Black - Status: Enable | G39: Passed | H39: 19/04/2026 | I39: Nữ
A40: GUI-CNV05 | B40: [Dropdown] Loại giảm giá | E40: - Text: Black - Status: Enable | F40: - Text: Black - Status: Enable | G40: Passed | H40: 19/04/2026 | I40: Nữ
A41: GUI-CNV06 | B41: [Input] Giá trị giảm | E41: - Text: Black - Status: Enable | F41: - Text: Black - Status: Enable | G41: Passed | H41: 19/04/2026 | I41: Nữ
A42: GUI-CNV07 | B42: [Input] Số lượng đã dùng | E42: - Text: Black - Status: Enable | F42: - Text: Black - Status: Enable | G42: Passed | H42: 19/04/2026 | I42: Nữ
A43: GUI-CNV08 | B43: [Input] Tổng số lượng phát hành | E43: - Text: Black - Status: Enable | F43: - Text: Black - Status: Enable | G43: Passed | H43: 19/04/2026 | I43: Nữ
A44: GUI-CNV09 | B44: [Input] Đơn tối thiểu | E44: - Text: Black - Status: Enable | F44: - Text: Black - Status: Enable | G44: Passed | H44: 19/04/2026 | I44: Nữ
A45: GUI-CNV10 | B45: [DatePicker] Ngày bắt đầu | E45: - Text: Black - Status: Enable | F45: - Text: Black - Status: Enable | G45: Passed | H45: 19/04/2026 | I45: Nữ
A46: GUI-CNV11 | B46: [DatePicker] Ngày kết thúc | E46: - Text: Black - Status: Enable | F46: - Text: Black - Status: Enable | G46: Passed | H46: 19/04/2026 | I46: Nữ
A47: GUI-CNV12 | B47: [Button] CẬP NHẬT THÔNG TIN | E47: - Text: Black - Status: Enable | F47: - Text: Black - Status: Enable | G47: Passed | H47: 19/04/2026 | I47: Nữ
A48: GUI-CNV13 | B48: [Button] HẾT HẠN | E48: - Text: Black - Status: Enable | F48: - Text: Black - Status: Enable | G48: Passed | H48: 19/04/2026 | I48: Nữ
A49: FUNCTION_SHOW Trang cập nhật voucher
A50: FUNC-CNV01 | B50: Kiểm tra load dữ liệu voucher | C50: 1. Truy cập trang 2. Quan sát | D50: Đăng nhập vào hệ thống | E50: Hiển thị đúng dữ liệu | F50: Hiển thị đúng dữ liệu | G50: Passed | H50: 19/04/2026 | I50: Nữ
A51: FUNC-CNV02 | B51: Kiểm tra cập nhật hợp lệ | C51: 1. Sửa thông tin 2. Click “Cập nhật” | D51: Đăng nhập vào hệ thống | E51: Không cho chỉnh sửa | F51: Không cho chỉnh sửa | G51: Passed | H51: 19/04/2026 | I51: Nữ
A52: FUNC-CNV03 | B52: Kiểm tra bỏ trống giá trị giảm | C52: 1. Xóa giá trị 2. Click cập nhật | D52: Đăng nhập vào hệ thống | E52: Không cho chỉnh sửa | F52: Không cho chỉnh sửa | G52: Passed | H52: 19/04/2026 | I52: Nữ
A53: FUNC-CNV04 | B53: Kiểm tra nhập chữ vào giá trị giảm | C53: 1. Nhập abc 2. Click cập nhật | D53: Đăng nhập vào hệ thống | E53: Không cho chỉnh sửa | F53: Không cho chỉnh sửa | G53: Passed | H53: 19/04/2026 | I53: Nữ
A54: FUNC-CNV05 | B54: Kiểm tra % > 100 | C54: 1. Nhập 150 2. Click cập nhật | D54: Đăng nhập vào hệ thống | E54: Không cho chỉnh sửa | F54: Không cho chỉnh sửa | G54: Passed | H54: 19/04/2026 | I54: Nữ
A55: FUNC-CNV06 | B55: Kiểm tra giá trị âm | C55: 1. Nhập -10 2. Click cập nhật | D55: Đăng nhập vào hệ thống | E55: Không cho chỉnh sửa | F55: Không cho chỉnh sửa | G55: Passed | H55: 19/04/2026 | I55: Nữ
A56: FUNC-CNV07 | B56: Kiểm tra số lượng phát hành < số đã dùng | C56: 1. Nhập nhỏ hơn 2. Lưu | D56: Đăng nhập vào hệ thống | E56: Báo lỗi và thoát khỏi màn hình | F56: Lưu thành công | G56: Failed | H56: 19/04/2026 | I56: Nữ | J56: Passed | K56: 19/04/2026 | L56: Nữ
A57: FUNC-CNV08 | B57: Kiểm tra ngày kết thúc < ngày bắt đầu | C57: 1. Chọn sai ngày 2. Lưu | D57: Đăng nhập vào hệ thống | E57: Báo lỗi và thoát khỏi màn hình | F57: Lưu thành công | G57: Failed | H57: 19/04/2026 | I57: Nữ | J57: Passed | K57: 19/04/2026 | L57: Nữ
A58: FUNC-CNV09 | B58: Kiểm tra bỏ trống ngày | C58: 1. Xóa ngày 2. Lưu | D58: Đăng nhập vào hệ thống | E58: Báo lỗi | F58: Báo lỗi | G58: Passed | H58: 19/04/2026 | I58: Nữ
A59: FUNC-CNV10 | B59: Kiểm tra cập nhật thành công | C59: 1. Nhập đúng 2. Lưu | D59: Đăng nhập vào hệ thống | E59: Hiển thị thông báo thành công | F59: Hiển thị thông báo thành công | G59: Passed | H59: 19/04/2026 | I59: Nữ
A60: FUNC-CNV11 | B60: Kiểm tra nút “HẾT HẠN” | C60: 1. Click nút 2. Reload | D60: Đăng nhập vào hệ thống | E60: Chuyển trạng thái hết hạn | F60: Chuyển trạng thái hết hạn | G60: Passed | H60: 19/04/2026 | I60: Nữ | L60: Nữ
A61: FUNC-CNV12 | B61: Kiểm tra trạng thái hết hạn | C61: 1. Voucher quá hạn | D61: Đăng nhập vào hệ thống | E61: Hiển thị “Đã hết hạn” | F61: Hiển thị “Đã hết hạn” | G61: Passed | H61: 19/04/2026 | I61: Nữ
A62: FUNC-CNV13 | B62: Kiểm tra áp dụng đơn hàng < min | C62: 1. Tạo đơn nhỏ 2. Apply | D62: Đăng nhập vào hệ thống | E62: Không áp dụng | F62: Không áp dụng | G62: Passed | H62: 19/04/2026 | I62: Nữ
A63: FUNC-CNV14 | B63: Kiểm tra áp dụng hợp lệ | C63: 1. Tạo đơn đủ điều kiện 2. Apply | D63: Đăng nhập vào hệ thống | E63: Giảm đúng % | F63: Giảm đúng % | G63: Passed | H63: 19/04/2026 | I63: Nữ
A64: FUNC-CNV15 | B64: Kiểm tra refresh dữ liệu | C64: 1. Update 2. Reload | D64: Đăng nhập vào hệ thống | E64: Dữ liệu giữ nguyên | F64: Dữ liệu giữ nguyên | G64: Passed | H64: 19/04/2026 | I64: Nữ

Sheet Danh sách đơn hàng
A1: Project Name | B1: XÂY DỰNG HỆ THỐNG THƯƠNG MẠI ĐIỆN TỬ MỸ PHẨM HAMONI COSMETIC VÀ CHATBOX AI TƯ VẤN KHÁCH HÀNG
A2: Module Code | B2: Danh sách đơn hàng
B3: Hoàn thành | C3: Lỗi | D3: Chưa kiểm tra | E3: Bị chăn | F3: Tổng số trường hợp thử nghiệm
A4: Round 1 | B4: 26 | C4: 0 | D4: =COUNTIF('Phiếu nhập kho'!G11:G21,"Untested") -> 0 | E4: =COUNTIF('Phiếu nhập kho'!G11:G21,"Blocked") -> 0 | F4: 26
A5: Round 2 | B5: 0 | C5: 0 | D5: =COUNTIF('Phiếu nhập kho'!J11:J21,"Untested") -> 0 | E5: =COUNTIF('Phiếu nhập kho'!J11:J21,"Blocked") -> 0 | F5: 26
A27: Test Case ID | B27: Mô tả | C27: Qui trình | D27: Điều kiện tiên quyết | E27: Kết quả mong đợi | F27: Kết quả thực tế | G27: Kết quả | J27: Kết quả | M27: Chú thích
J28: Vòng 2
G29: Trạng thái | H29: Ngày kiểm tra | I29: Người kiểm tra | J29: Trạng thái | K29: Ngày kiểm tra | L29: Người kiểm tra
A30: GUI_SHOW Trang danh sách đơn hàng
A31: GUI-DSDH01 | B31: [Title] QUẢN LÝ ĐƠN HÀNG | E31: - Text: Black - Status: Enable | F31: - Text: Black - Status: Enable | G31: Passed | H31: 19/04/2026 | I31: Nữ
A32: GUI-DSDH02 | B32: [Dropdown] Tất cả trạng thái | E32: - Text: Black - Status: Enable | F32: - Text: Black - Status: Enable | G32: Passed | H32: 19/04/2026 | I32: Nữ
A33: GUI-DSDH03 | B33: [Input] Tìm kiếm đơn hàng | E33: - Text: Black - Status: Enable | F33: - Text: Black - Status: Enable | G33: Passed | H33: 19/04/2026 | I33: Nữ
A34: GUI-DSDH04 | B34: [DatePicker] Lọc theo ngày | E34: - Text: Black - Status: Enable | F34: - Text: Black - Status: Enable | G34: Passed | H34: 19/04/2026 | I34: Nữ
A35: GUI-DSDH05 | B35: [Table] Danh sách đơn hàng | E35: - Text: Black - Status: Enable | F35: - Text: Black - Status: Enable | G35: Passed | H35: 19/04/2026 | I35: Nữ
A36: GUI-DSDH06 | B36: [Column] Mã đơn | E36: - Text: Black - Status: Enable | F36: - Text: Black - Status: Enable | G36: Passed | H36: 19/04/2026 | I36: Nữ
A37: GUI-DSDH07 | B37: [Column] Ngày đặt | E37: - Text: Black - Status: Enable | F37: - Text: Black - Status: Enable | G37: Passed | H37: 19/04/2026 | I37: Nữ
A38: GUI-DSDH08 | B38: [Column] Khách hàng | E38: - Text: Black - Status: Enable | F38: - Text: Black - Status: Enable | G38: Passed | H38: 19/04/2026 | I38: Nữ
A39: GUI-DSDH09 | B39: [Column] Tổng tiền | E39: - Text: Black - Status: Enable | F39: - Text: Black - Status: Enable | G39: Passed | H39: 19/04/2026 | I39: Nữ
A40: GUI-DSDH10 | B40: [Column] Trạng thái | E40: - Text: Black - Status: Enable | F40: - Text: Black - Status: Enable | G40: Passed | H40: 19/04/2026 | I40: Nữ
A41: GUI-DSDH11 | B41: [Tag] Chờ xác nhận | E41: - Text: Black - Status: Enable | F41: - Text: Black - Status: Enable | G41: Passed | H41: 19/04/2026 | I41: Nữ
A42: GUI-DSDH12 | B42: [Tag] Đang giao | E42: - Text: Black - Status: Enable | F42: - Text: Black - Status: Enable | G42: Passed | H42: 19/04/2026 | I42: Nữ
A43: GUI-DSDH13 | B43: [Pagination] Phân trang | H43: 19/04/2026
A44: GUI-DSDH14 | B44: [Button] Chuyển trang | E44: - Text: Black - Status: Enable | F44: - Text: Black - Status: Enable | G44: Passed | H44: 19/04/2026 | I44: Nữ
A45: FUNCTION_SHOW Trang danh sách đơn hàng
A46: FUNC-DSDH01 | B46: Kiểm tra hiển thị danh sách đơn | C46: 1. Truy cập trang 2. Quan sát | D46: Đăng nhập vào hệ thống | E46: Hiển thị đúng dữ liệu | F46: Hiển thị đúng dữ liệu | G46: Passed | H46: 19/04/2026 | I46: Nữ
A47: FUNC-DSDH02 | B47: Kiểm tra tìm kiếm theo mã đơn | C47: 1. Nhập mã 2. Enter | D47: Đăng nhập vào hệ thống | E47: Trả đúng đơn | F47: Trả đúng đơn | G47: Passed | H47: 19/04/2026 | I47: Nữ
A48: FUNC-DSDH03 | B48: Kiểm tra tìm kiếm theo tên KH | C48: 1. Nhập tên 2. Enter | D48: Đăng nhập vào hệ thống | E48: Trả đúng kết quả | F48: Trả đúng kết quả | G48: Passed | H48: 19/04/2026 | I48: Nữ
A49: FUNC-DSDH04 | B49: Kiểm tra tìm kiếm không tồn tại | C49: 1. Nhập sai 2. Enter | D49: Đăng nhập vào hệ thống | E49: Không có dữ liệu | F49: Không có dữ liệu | G49: Passed | H49: 19/04/2026 | I49: Nữ
A50: FUNC-DSDH05 | B50: Kiểm tra lọc trạng thái | C50: 1. Chọn trạng thái 2. Quan sát | D50: Đăng nhập vào hệ thống | E50: Lọc đúng | F50: Lọc đúng | G50: Passed | H50: 19/04/2026 | I50: Nữ
A51: FUNC-DSDH06 | B51: Kiểm tra lọc ngày hợp lệ | C51: 1. Chọn ngày 2. Lọc | D51: Đăng nhập vào hệ thống | E51: Hiển thị đúng | F51: Hiển thị đúng | G51: Passed | H51: 19/04/2026 | I51: Nữ
A52: FUNC-DSDH07 | B52: Kiểm tra ngày sai (from > to) | C52: 1. Chọn sai 2. Lọc | D52: Đăng nhập vào hệ thống | E52: Báo lỗi / không lọc | F52: Báo lỗi / không lọc | G52: Passed | H52: 19/04/2026 | I52: Nữ
A53: FUNC-DSDH08 | B53: Kiểm tra hiển thị tổng tiền | C53: 1. Xem danh sách | D53: Đăng nhập vào hệ thống | E53: Hiển thị đúng VNĐ | F53: Hiển thị đúng VNĐ | G53: Passed | H53: 19/04/2026 | I53: Nữ
A54: FUNC-DSDH09 | B54: Kiểm tra trạng thái đơn | C54: 1. Xem trạng thái | D54: Đăng nhập vào hệ thống | E54: Hiển thị đúng | F54: Hiển thị đúng | G54: Passed | H54: 19/04/2026 | I54: Nữ
A55: FUNC-DSDH10 | B55: Kiểm tra phân trang | C55: 1. Click trang 2 | D55: Đăng nhập vào hệ thống | E55: Load đúng data | F55: Load đúng data | G55: Passed | H55: 19/04/2026 | I55: Nữ
A56: FUNC-DSDH11 | B56: Kiểm tra refresh trang | C56: 1. Reload | D56: Đăng nhập vào hệ thống | E56: Dữ liệu không đổi | F56: Dữ liệu không đổi | G56: Passed | H56: 19/04/2026 | I56: Nữ
A57: FUNC-DSDH12 | B57: Kiểm tra dữ liệu null | C57: 1. Load data lỗi | D57: Đăng nhập vào hệ thống | E57: Không crash | F57: Không crash | G57: Passed | H57: 19/04/2026 | I57: Nữ

Sheet Chi tiết đơn hàng
A1: Project Name | B1: XÂY DỰNG HỆ THỐNG THƯƠNG MẠI ĐIỆN TỬ MỸ PHẨM HAMONI COSMETIC VÀ CHATBOX AI TƯ VẤN KHÁCH HÀNG
A2: Module Code | B2: Danh sách và thêm voucher
B3: Hoàn thành | C3: Lỗi | D3: Chưa kiểm tra | E3: Bị chăn | F3: Tổng số trường hợp thử nghiệm
A4: Round 1 | B4: 26 | C4: 2 | D4: =COUNTIF('Phiếu nhập kho'!G11:G21,"Untested") -> 0 | E4: =COUNTIF('Phiếu nhập kho'!G11:G21,"Blocked") -> 0 | F4: 28
A5: Round 2 | B5: 28 | C5: 0 | D5: =COUNTIF('Phiếu nhập kho'!J11:J21,"Untested") -> 0 | E5: =COUNTIF('Phiếu nhập kho'!J11:J21,"Blocked") -> 0 | F5: 28
A30: Test Case ID | B30: Mô tả | C30: Qui trình | D30: Điều kiện tiên quyết | E30: Kết quả mong đợi | F30: Kết quả thực tế | G30: Kết quả | J30: Kết quả | M30: Chú thích
G31: Vòng 1 | J31: Vòng 2
G32: Trạng thái | H32: Ngày kiểm tra | I32: Người kiểm tra | J32: Trạng thái | K32: Ngày kiểm tra | L32: Người kiểm tra
A33: GUI_SHOW Trang chi tiết đơn hàng
A34: GUI-CTDH01 | B34: [Title] XỬ LÝ ĐƠN HÀNG & CẬP NHẬT TRẠNG THÁI | E34: - Text: Black - Status: Enable | F34: - Text: Black - Status: Enable | G34: Passed | I34: Nữ
A35: GUI-CTDH02 | B35: [Button] Quay lại danh sách | E35: - Text: Black - Status: Enable | F35: - Text: Black - Status: Enable | G35: Passed | I35: Nữ
A36: GUI-CTDH03 | B36: [Info] Thông tin khách hàng | E36: - Text: Black - Status: Enable | F36: - Text: Black - Status: Enable | G36: Passed | I36: Nữ
A37: GUI-CTDH04 | B37: [Info] Địa chỉ giao hàng | E37: - Text: Black - Status: Enable | F37: - Text: Black - Status: Enable | G37: Passed | I37: Nữ
A38: GUI-CTDH05 | B38: [Table] Danh sách sản phẩm | E38: - Text: Black - Status: Enable | F38: - Text: Black - Status: Enable | G38: Passed | I38: Nữ
A39: GUI-CTDH06 | B39: [Column] Tên sản phẩm | E39: - Text: Black - Status: Enable | F39: - Text: Black - Status: Enable | G39: Passed | I39: Nữ
A40: GUI-CTDH07 | B40: [Column] Số lượng | E40: - Text: Black - Status: Enable | F40: - Text: Black - Status: Enable | G40: Passed | I40: Nữ
A41: GUI-CTDH08 | B41: [Column] Giá | E41: - Text: Black - Status: Enable | F41: - Text: Black - Status: Enable | G41: Passed | I41: Nữ
A42: GUI-CTDH09 | B42: [Text] Tạm tính / Voucher / Ship | E42: - Text: Black - Status: Enable | F42: - Text: Black - Status: Enable | G42: Passed | I42: Nữ
A43: GUI-CTDH10 | B43: [Text] Tổng tiền | E43: - Text: Black - Status: Enable | F43: - Text: Black - Status: Enable | G43: Passed | I43: Nữ
A44: GUI-CTDH11 | B44: [Dropdown] Trạng thái đơn hàng | E44: - Text: Black - Status: Enable | F44: - Text: Black - Status: Enable | G44: Passed | I44: Nữ
